Workbook

Sheet I1a-comp
A1: =I1a!A1 -> REGRESSOR | B1: =I1a!B1 -> COEFFICIENT | D1: =I1a_orig!A1 -> REGRESSOR | E1: =I1a_orig!B1 -> COEFFICIENT | G1: comp
A2: =I1a!A2 -> eduSampleFlag | B2: =I1a!B2 -> 0.21420725 | D2: =I1a_orig!A2 -> Ded | E2: =I1a_orig!B2 -> 0.21420725 | G2: =B2-E2 -> 7.4940054e-16
A3: =I1a!A3 -> demMaleFlag | B3: =I1a!B3 -> -0.056755813 | D3: =I1a_orig!A3 -> Dgn | E3: =I1a_orig!B3 -> -0.056755813 | G3: =B3-E3 -> -8.3266727e-17
A4: =I1a!A4 -> demAge | B4: =I1a!B4 -> -0.014317052 | D4: =I1a_orig!A4 -> Dag | E4: =I1a_orig!B4 -> -0.014317052 | G4: =B4-E4 -> 1.1275703e-16
A5: =I1a!A5 -> demAgeSq | B5: =I1a!B5 -> 0.00023304201 | D5: =I1a_orig!A5 -> Dag_sq | E5: =I1a_orig!B5 -> 0.00023304201 | G5: =B5-E5 -> -8.4025668e-19
A6: =I1a!A6 -> healthPhysicalPcsL1 | B6: =I1a!B6 -> 0.012631804 | D6: =I1a_orig!A6 -> Dhe_pcs_L1 | E6: =I1a_orig!B6 -> 0.012631804 | G6: =B6-E6 -> 4.3368087e-17
A7: =I1a!A7 -> healthMentalMcsL1 | B7: =I1a!B7 -> 0.0052351586 | D7: =I1a_orig!A7 -> Dhe_mcs_L1 | E7: =I1a_orig!B7 -> 0.0052351586 | G7: =B7-E7 -> 6.505213e-17
A8: =I1a!A8 -> yCapitalPersMonthL1 | B8: =I1a!B8 -> 0.35965781 | D8: =I1a_orig!A8 -> Ypncp_L1 | E8: =I1a_orig!B8 -> 0.35965781 | G8: =B8-E8 -> 0
A9: =I1a!A9 -> yEmpPersGrossMonthL1 | B9: =I1a!B9 -> 0.070213024 | D9: =I1a_orig!A9 -> Yplgrs_dv_L1 | E9: =I1a_orig!B9 -> 0.070213024 | G9: =B9-E9 -> 1.6237012e-15
A10: =I1a!A10 -> yEmpPersGrossMonthL2 | B10: =I1a!B10 -> 0.028579125 | D10: =I1a_orig!A10 -> Yplgrs_dv_L2 | E10: =I1a_orig!B10 -> 0.028579125 | G10: =B10-E10 -> 0
A11: =I1a!A11 -> yCapitalPersMonthL2 | B11: =I1a!B11 -> 0.24175926 | D11: =I1a_orig!A11 -> Ypncp_L2 | E11: =I1a_orig!B11 -> 0.24175926 | G11: =B11-E11 -> 0
A12: =I1a!A12 -> eduSampleFlag_Male | B12: =I1a!B12 -> 0.15881231 | D12: =I1a_orig!A12 -> Ded_Dgn | E12: =I1a_orig!B12 -> 0.15881231 | G12: =B12-E12 -> 0
A13: =I1a!A13 -> eduSampleFlag_PcsL1 | B13: =I1a!B13 -> 0.0060994171 | D13: =I1a_orig!A13 -> Ded_Dhe_pcs_L1 | E13: =I1a_orig!B13 -> 0.0060994171 | G13: =B13-E13 -> 2.8622937e-17
... A42: =I1a!A42 -> Constant | B42: =I1a!B42 -> -2.0859754 | D42: =I1a_orig!A42 -> Constant | E42: =I1a_orig!B42 -> -2.0859754 | G42: =B42-E42 -> -2.9753977e-14

Sheet I1b-comp
A1: =I1b!A1 -> REGRESSOR | B1: =I1b!B1 -> COEFFICIENT | D1: =I1b_orig!A1 -> REGRESSOR | E1: =I1b_orig!B1 -> COEFFICIENT | G1: comp
A2: =I1b!A2 -> demMaleFlag | B2: =I1b!B2 -> 0.16808438 | D2: =I1b_orig!A2 -> Dgn | E2: =I1b_orig!B2 -> 0.16808438 | G2: =B2-E2 -> -1.2850832e-14
A3: =I1b!A3 -> demAge | B3: =I1b!B3 -> 0.035590133 | D3: =I1b_orig!A3 -> Dag | E3: =I1b_orig!B3 -> 0.035590133 | G3: =B3-E3 -> -5.0168203e-15
A4: =I1b!A4 -> demAgeSq | B4: =I1b!B4 -> -0.0002907999 | D4: =I1b_orig!A4 -> Dag_sq | E4: =I1b_orig!B4 -> -0.0002907999 | G4: =B4-E4 -> 3.8977068e-17
A5: =I1b!A5 -> eduHighestC4Low | B5: =I1b!B5 -> -0.70895009 | D5: =I1b_orig!A5 -> Deh_c4_Low | E5: =I1b_orig!B5 -> -0.70895009 | G5: =B5-E5 -> -7.571721e-14
A6: =I1b!A6 -> eduHighestC4Medium | B6: =I1b!B6 -> -0.60464798 | D6: =I1b_orig!A6 -> Deh_c4_Medium | E6: =I1b_orig!B6 -> -0.60464798 | G6: =B6-E6 -> -5.0737192e-14
A7: =I1b!A7 -> eduHighestC4High | B7: =I1b!B7 -> -0.62013452 | D7: =I1b_orig!A7 -> Deh_c4_High | E7: =I1b_orig!B7 -> -0.62013452 | G7: =B7-E7 -> -6.17284e-14
A8: =I1b!A8 -> labStatusC4StudentL1 | B8: =I1b!B8 -> 0.27701097 | D8: =I1b_orig!A8 -> Les_c4_Student_L1 | E8: =I1b_orig!B8 -> 0.27701097 | G8: =B8-E8 -> 2.9887204e-13
A9: =I1b!A9 -> labStatusC4NotEmployedL1 | B9: =I1b!B9 -> -0.13083018 | D9: =I1b_orig!A9 -> Les_c4_NotEmployed_L1 | E9: =I1b_orig!B9 -> -0.13083018 | G9: =B9-E9 -> 3.7997383e-13
A10: =I1b!A10 -> labStatusC4RetiredL1 | B10: =I1b!B10 -> -0.22059529 | D10: =I1b_orig!A10 -> Les_c4_Retired_L1 | E10: =I1b_orig!B10 -> -0.22059529 | G10: =B10-E10 -> 4.086731e-13
A11: =I1b!A11 -> demCompHhC4CoupleChL1 | B11: =I1b!B11 -> -0.065898543 | D11: =I1b_orig!A11 -> Dhhtp_c4_CoupleChildren_L1 | E11: =I1b_orig!B11 -> -0.065898543 | G11: =B11-E11 -> 4.2466031e-15
A12: =I1b!A12 -> demCompHhC4SingleNoChL1 | B12: =I1b!B12 -> -0.019230616 | D12: =I1b_orig!A12 -> Dhhtp_c4_SingleNoChildren_L1 | E12: =I1b_orig!B12 -> -0.019230616 | G12: =B12-E12 -> -7.5286999e-15
A13: =I1b!A13 -> demCompHhC4SingleChL1 | B13: =I1b!B13 -> 0.73099038 | D13: =I1b_orig!A13 -> Dhhtp_c4_SingleChildren_L1 | E13: =I1b_orig!B13 -> 0.73099038 | G13: =B13-E13 -> -1.8873791e-15
... A40: =I1b!A40 -> Constant | B40: =I1b!B40 -> 2.0575397 | D40: =I1b_orig!A40 -> Constant | E40: =I1b_orig!B40 -> 2.0575397 | G40: =B40-E40 -> -1.6564528e-13

Sheet I2b-comp
A1: =I2b!A1 -> REGRESSOR | B1: =I2b!B1 -> COEFFICIENT | D1: =I2b_orig!A1 -> REGRESSOR | E1: =I2b_orig!B1 -> COEFFICIENT | G1: comp
A2: =I2b!A2 -> demMaleFlag | B2: =I2b!B2 -> 0.26086921 | D2: =I2b_orig!A2 -> Dgn | E2: =I2b_orig!B2 -> 0.26086921 | G2: =B2-E2 -> 2.942091e-15
A3: =I2b!A3 -> demAge | B3: =I2b!B3 -> -0.010083303 | D3: =I2b_orig!A3 -> Dag | E3: =I2b_orig!B3 -> -0.010083303 | G3: =B3-E3 -> -7.979728e-17
A4: =I2b!A4 -> eduHighestC4High | B4: =I2b!B4 -> 0.62675371 | D4: =I2b_orig!A4 -> Deh_c4_High | E4: =I2b_orig!B4 -> 0.62675371 | G4: =B4-E4 -> -1.2434498e-14
A5: =I2b!A5 -> eduHighestC4Medium | B5: =I2b!B5 -> 0.27465082 | D5: =I2b_orig!A5 -> Deh_c4_Medium | E5: =I2b_orig!B5 -> 0.27465082 | G5: =B5-E5 -> -3.6082248e-15
A6: =I2b!A6 -> demCompHhC4CoupleChL1 | B6: =I2b!B6 -> 0.046534826 | D6: =I2b_orig!A6 -> Dhhtp_c4_CoupleChildren_L1 | E6: =I2b_orig!B6 -> 0.046534826 | G6: =B6-E6 -> 3.6567971e-15
A7: =I2b!A7 -> demCompHhC4SingleNoChL1 | B7: =I2b!B7 -> 0.013678859 | D7: =I2b_orig!A7 -> Dhhtp_c4_SingleNoChildren_L1 | E7: =I2b_orig!B7 -> 0.013678859 | G7: =B7-E7 -> -2.9802549e-15
A8: =I2b!A8 -> demCompHhC4SingleChL1 | B8: =I2b!B8 -> 0.12488022 | D8: =I2b_orig!A8 -> Dhhtp_c4_SingleChildren_L1 | E8: =I2b_orig!B8 -> 0.12488022 | G8: =B8-E8 -> -2.9698466e-15
A9: =I2b!A9 -> healthPhysicalPcsL1 | B9: =I2b!B9 -> 0.0062493874 | D9: =I2b_orig!A9 -> Dhe_pcs_L1 | E9: =I2b_orig!B9 -> 0.0062493874 | G9: =B9-E9 -> -7.8062556e-18
A10: =I2b!A10 -> healthMentalMcsL1 | B10: =I2b!B10 -> 0.00308013 | D10: =I2b_orig!A10 -> Dhe_mcs_L1 | E10: =I2b_orig!B10 -> 0.00308013 | G10: =B10-E10 -> -6.0715322e-18
A11: =I2b!A11 -> yPensPersGrossMonthL1 | B11: =I2b!B11 -> 0.25503875 | D11: =I2b_orig!A11 -> Ypnoab_L1 | E11: =I2b_orig!B11 -> 0.25503875 | G11: =B11-E11 -> 0
A12: =I2b!A12 -> yPensPersGrossMonthL2 | B12: =I2b!B12 -> 0.1042284 | D12: =I2b_orig!A12 -> Ypnoab_L2 | E12: =I2b_orig!B12 -> 0.1042284 | G12: =B12-E12 -> 2.220446e-16
A13: =I2b!A13 -> demRgnUKC | B13: =I2b!B13 -> -0.10294962 | D13: =I2b_orig!A13 -> demRgnUKC | E13: =I2b_orig!B13 -> -0.10294962 | G13: =B13-E13 -> -9.15934e-16
... A30: =I2b!A30 -> Constant | B30: =I2b!B30 -> 4.3262399 | D30: =I2b_orig!A30 -> Constant | E30: =I2b_orig!B30 -> 4.3262399 | G30: =B30-E30 -> 0

Sheet I3a-comp
A1: =I3a!A1 -> REGRESSOR | B1: =I3a!B1 -> COEFFICIENT | D1: =I3a_orig!A1 -> REGRESSOR | E1: =I3a_orig!B1 -> COEFFICIENT | G1: comp
A2: =I3a!A2 -> demMaleFlag | B2: =I3a!B2 -> 0.35383796 | D2: =I3a_orig!A2 -> Dgn | E2: =I3a_orig!B2 -> 0.35383796 | G2: =B2-E2 -> 0
A3: =I3a!A3 -> demPensAgeFlag | B3: =I3a!B3 -> 0.21625282 | D3: =I3a_orig!A3 -> Reached_Retirement_Age | E3: =I3a_orig!B3 -> 0.21625282 | G3: =B3-E3 -> 0
A4: =I3a!A4 -> eduHighestC4High | B4: =I3a!B4 -> 0.7941064 | D4: =I3a_orig!A4 -> Deh_c4_High | E4: =I3a_orig!B4 -> 0.7941064 | G4: =B4-E4 -> 0
A5: =I3a!A5 -> eduHighestC4Medium | B5: =I3a!B5 -> 0.60458273 | D5: =I3a_orig!A5 -> Deh_c4_Medium | E5: =I3a_orig!B5 -> 0.60458273 | G5: =B5-E5 -> 0
A6: =I3a!A6 -> labStatusC4NotEmployedL1 | B6: =I3a!B6 -> -1.1673515 | D6: =I3a_orig!A6 -> Les_c4_NotEmployed_L1 | E6: =I3a_orig!B6 -> -1.1673515 | G6: =B6-E6 -> 0
A7: =I3a!A7 -> demCompHhC4CoupleChL1 | B7: =I3a!B7 -> 0.071977454 | D7: =I3a_orig!A7 -> Dhhtp_c4_CoupleChildren_L1 | E7: =I3a_orig!B7 -> 0.071977454 | G7: =B7-E7 -> 1.3877788e-16
A8: =I3a!A8 -> demCompHhC4SingleNoChL1 | B8: =I3a!B8 -> 0.028802886 | D8: =I3a_orig!A8 -> Dhhtp_c4_SingleNoChildren_L1 | E8: =I3a_orig!B8 -> 0.028802886 | G8: =B8-E8 -> 1.6653345e-16
A9: =I3a!A9 -> demCompHhC4SingleChL1 | B9: =I3a!B9 -> 0.25579166 | D9: =I3a_orig!A9 -> Dhhtp_c4_SingleChildren_L1 | E9: =I3a_orig!B9 -> 0.25579166 | G9: =B9-E9 -> 0
A10: =I3a!A10 -> healthPhysicalPcsL1 | B10: =I3a!B10 -> 0.003924723 | D10: =I3a_orig!A10 -> Dhe_pcs_L1 | E10: =I3a_orig!B10 -> 0.003924723 | G10: =B10-E10 -> 9.5409791e-18
A11: =I3a!A11 -> healthMentalMcsL1 | B11: =I3a!B11 -> 0.0037619527 | D11: =I3a_orig!A11 -> Dhe_mcs_L1 | E11: =I3a_orig!B11 -> 0.0037619527 | G11: =B11-E11 -> 3.989864e-17
A12: =I3a!A12 -> labWageHrlyLogL1 | B12: =I3a!B12 -> 0.0043469926 | D12: =I3a_orig!A12 -> Hourly_wage_L1 | E12: =I3a_orig!B12 -> 0.0043469926 | G12: =B12-E12 -> 0
A13: =I3a!A13 -> demRgnUKC | B13: =I3a!B13 -> 0.059542 | D13: =I3a_orig!A13 -> demRgnUKC | E13: =I3a_orig!B13 -> 0.059542 | G13: =B13-E13 -> 6.0368377e-16
... A30: =I3a!A30 -> Constant | B30: =I3a!B30 -> -0.056274553 | D30: =I3a_orig!A30 -> Constant | E30: =I3a_orig!B30 -> -0.056274553 | G30: =B30-E30 -> -4.3437476e-15

Sheet I3b-comp
A1: =I3b!A1 -> REGRESSOR | B1: =I3b!B1 -> COEFFICIENT | D1: =I3b_orig!A1 -> REGRESSOR | E1: =I3b_orig!B1 -> COEFFICIENT | G1: comp
A2: =I3b!A2 -> demMaleFlag | B2: =I3b!B2 -> 0.44711177 | D2: =I3b_orig!A2 -> Dgn | E2: =I3b_orig!B2 -> 0.44711177 | G2: =B2-E2 -> 4.6074256e-15
A3: =I3b!A3 -> demAge | B3: =I3b!B3 -> -0.059093503 | D3: =I3b_orig!A3 -> Dag | E3: =I3b_orig!B3 -> -0.059093503 | G3: =B3-E3 -> -6.9388939e-17
A4: =I3b!A4 -> eduHighestC4High | B4: =I3b!B4 -> 0.86976754 | D4: =I3b_orig!A4 -> Deh_c4_High | E4: =I3b_orig!B4 -> 0.86976754 | G4: =B4-E4 -> 1.8762769e-14
A5: =I3b!A5 -> eduHighestC4Medium | B5: =I3b!B5 -> 0.45277277 | D5: =I3b_orig!A5 -> Deh_c4_Medium | E5: =I3b_orig!B5 -> 0.45277277 | G5: =B5-E5 -> 1.6597834e-14
A6: =I3b!A6 -> labStatusC4NotEmployedL1 | B6: =I3b!B6 -> -0.45637809 | D6: =I3b_orig!A6 -> Les_c4_NotEmployed_L1 | E6: =I3b_orig!B6 -> -0.45637809 | G6: =B6-E6 -> 5.3845817e-15
A7: =I3b!A7 -> demCompHhC4CoupleChL1 | B7: =I3b!B7 -> -0.14248881 | D7: =I3b_orig!A7 -> Dhhtp_c4_CoupleChildren_L1 | E7: =I3b_orig!B7 -> -0.14248881 | G7: =B7-E7 -> 2.4980018e-16
A8: =I3b!A8 -> demCompHhC4SingleNoChL1 | B8: =I3b!B8 -> 0.027057424 | D8: =I3b_orig!A8 -> Dhhtp_c4_SingleNoChildren_L1 | E8: =I3b_orig!B8 -> 0.027057424 | G8: =B8-E8 -> 3.2855663e-15
A9: =I3b!A9 -> demCompHhC4SingleChL1 | B9: =I3b!B9 -> -0.23594699 | D9: =I3b_orig!A9 -> Dhhtp_c4_SingleChildren_L1 | E9: =I3b_orig!B9 -> -0.23594699 | G9: =B9-E9 -> 7.2164497e-16
A10: =I3b!A10 -> healthPhysicalPcsL1 | B10: =I3b!B10 -> 0.012626712 | D10: =I3b_orig!A10 -> Dhe_pcs_L1 | E10: =I3b_orig!B10 -> 0.012626712 | G10: =B10-E10 -> 2.6020852e-17
A11: =I3b!A11 -> healthMentalMcsL1 | B11: =I3b!B11 -> 0.0026813622 | D11: =I3b_orig!A11 -> Dhe_mcs_L1 | E11: =I3b_orig!B11 -> 0.0026813622 | G11: =B11-E11 -> 3.0791342e-17
A12: =I3b!A12 -> labWageHrlyLogL1 | B12: =I3b!B12 -> 0.0025785151 | D12: =I3b_orig!A12 -> Hourly_wage_L1 | E12: =I3b_orig!B12 -> 0.0025785151 | G12: =B12-E12 -> -1.3314003e-16
A13: =I3b!A13 -> demRgnUKC | B13: =I3b!B13 -> -0.10610904 | D13: =I3b_orig!A13 -> demRgnUKC | E13: =I3b_orig!B13 -> -0.10610904 | G13: =B13-E13 -> -1.6792123e-15
... A30: =I3b!A30 -> Constant | B30: =I3b!B30 -> 9.1092833 | D30: =I3b_orig!A30 -> Constant | E30: =I3b_orig!B30 -> 9.1092833 | G30: =B30-E30 -> 0

Sheet Info
A1: Description: | B1: This file contains regression estimates used by processes I1 (capital income), I2 (private pension, retired last year), I3 (private pension income, not retired last year)
A2: Authors: | B2: Patryk Bronka, Justin Van de Ven, Daria Popova, Aleksandra Kolndrekaj, Ashley Burdett
A3: Last edit: 15 April 2026 (DP)
A5: Process: | B5: Description:
A7: Process I1a | B7: Prob. receive capital income
A8: Process I1b | B8: Capital income amount
A9: Process I2b | B9: Private pension income amount
A10: Process I3a | B10: Prob. receive private pension income
A11: Process I3b | B11: Private pension income amount
A17: Notes: | B17: Estimation sample: UK_ipop2.dta with grossing up weight dwt
B18: Conditions for processes are defined as globals in master.do
B19: Combined former capital income processes I3a and I3b and renamed as I1a and I1b
B20: Income variables are IHS transformed.

Sheet Gof
A1: Goodness of fit
A3: I1a - Receive capital income
A4: Pseudo R-squared | B4: 0.2934017 | E4: Chi^2 | F4: 26802.848
A5: N | B5: 267326 | E5: Log likelihood | F5: -1.0269119e+08
A7: I1b - Amount of capital income
A8: R-squared | B8: 0.34112607
A9: N | B9: 113735
A11: I2b - Amount of private pension income
A12: R-squared | B12: 0.43389448
A13: N | B13: 56460
A15: I3a - Receive private pension income
A16: Pseudo R-squared | B16: 0.092207592 | E16: Chi^2 | F16: 354.64954
A17: N | B17: 4843 | E17: Log likelihood | F17: -2266083.1
A19: I3b - Amount of private pension income
A20: R-squared | B20: 0.24828659
A21: N | B21: 2910

Sheet I1a_orig
A1: REGRESSOR | B1: COEFFICIENT | C1: Ded | D1: Dgn | E1: Dag | F1: Dag_sq | G1: Dhe_pcs_L1 | H1: Dhe_mcs_L1 | I1: Ypncp_L1 | J1: Yplgrs_dv_L1 | K1: Yplgrs_dv_L2 | L1: Ypncp_L2 | M1: Ded_Dgn | N1: Ded_Dhe_pcs_L1 | O1: Ded_Dhe_mcs_L1 | P1: Ded_Ypncp_L1 | Q1: Ded_Ypncp_L2 | R1: Deh_c4_Low | S1: Deh_c4_Medium | T1: Les_c4_Student_L1 | U1: Les_c4_NotEmployed_L1 | V1: Les_c4_Retired_L1 | W1: Dhhtp_c4_CoupleChildren_L1 | X1: Dhhtp_c4_SingleNoChildren_L1 | Y1: Dhhtp_c4_SingleChildren_L1 | Z1: demRgnUKC | AA1: demRgnUKD | AB1: demRgnUKE | AC1: demRgnUKF | AD1: demRgnUKG | AE1: demRgnUKH | AF1: demRgnUKJ | AG1: demRgnUKK | AH1: demRgnUKL | AI1: demRgnUKM | AJ1: demRgnUKN | AK1: Year_transformed | AL1: Y2020 | AM1: Y2021 | AN1: demEthnC4Asian | AO1: demEthnC4Black | AP1: demEthnC4Other | AQ1: Constant
A2: Ded | B2: 0.21420725 | C2: 0.005500625 | D2: 0.00010437532 | E2: 1.1381083e-05 | F2: -1.1376512e-07 | G2: 1.6855851e-06 | H2: -1.4793555e-08 | I2: 1.9212086e-06 | J2: 1.5108493e-05 | K2: 7.4411552e-07 | L2: 1.7812894e-06 | M2: -0.002124984 | N2: -3.744376e-05 | O2: -1.795159e-05 | P2: -2.3320289e-06 | Q2: 5.3071994e-06 | R2: 0.0002395395 | S2: 0.000272546 | T2: -2.9069659e-05 | U2: 9.4949059e-05 | V2: 0.00012559273 | W2: -4.6086985e-05 | X2: 6.3737241e-05 | Y2: -7.8446208e-05 | Z2: -0.00011421268 | AA2: -7.1157357e-05 | AB2: -9.5827275e-05 | AC2: -7.5239724e-05 | AD2: -9.2088125e-05 | AE2: -0.0001005375 | AF2: -7.2673065e-05 | AG2: -8.2670602e-05 | AH2: -9.8637386e-05 | AI2: -8.7011231e-05 | AJ2: -8.8532193e-05 | AK2: 2.1242778e-06 | AL2: 4.5934602e-05 | AM2: 2.0112865e-05 | AN2: -3.7968975e-05 | AO2: -4.4799441e-05 | AP2: 1.4140825e-05 | AQ2: -0.00066964333
A3: Dgn | B3: -0.056755813 | C3: 0.00010437532 | D3: 0.00026559535 | E3: 2.3942156e-06 | F3: -2.243003e-08 | G3: -2.8477599e-07 | H3: -9.372536e-07 | I3: -2.3937803e-06 | J3: -3.0704306e-05 | K3: -1.9048571e-06 | L3: -2.7785158e-06 | M3: -0.00024540017 | N3: -2.2482876e-07 | O3: -1.1886241e-07 | P3: 6.8650971e-07 | Q3: 5.7708739e-07 | R3: -1.4602148e-05 | S3: -1.8426353e-05 | T3: -0.00022591876 | U3: -0.00022909429 | V3: -0.00022585383 | W3: -2.033829e-06 | X3: 2.5054275e-05 | Y3: 7.9156898e-05 | Z3: -1.8098109e-07 | AA3: 9.1584063e-07 | AB3: 1.3378984e-06 | AC3: -6.1549163e-06 | AD3: -8.3535788e-07 | AE3: -7.1303798e-06 | AF3: 1.7914994e-06 | AG3: 7.4404253e-07 | AH3: -2.1933938e-06 | AI3: -3.769157e-06 | AJ3: -1.980747e-05 | AK3: -3.1387158e-07 | AL3: 9.9054125e-07 | AM3: 4.162825e-06 | AN3: 1.3091236e-05 | AO3: -2.2210526e-05 | AP3: -1.2024614e-05 | AQ3: 0.00014698695
A4: Dag | B4: -0.014317052 | C4: 1.1381083e-05 | D4: 2.3942156e-06 | E4: 7.34292e-06 | F4: -6.7980001e-08 | G4: 4.0355518e-08 | H4: 2.9378808e-08 | I4: -6.2259647e-07 | J4: -1.9567822e-06 | K4: -1.7064951e-06 | L4: -6.8573772e-07 | M4: -3.3013538e-06 | N4: 2.308637e-07 | O4: 1.615724e-08 | P4: -1.4561782e-06 | Q4: 1.6012757e-06 | R4: 1.4529091e-06 | S4: 3.8577225e-08 | T4: 1.4331693e-05 | U4: -1.9662884e-05 | V4: -1.3674086e-05 | W4: 4.6946302e-06 | X4: 1.4166433e-05 | Y4: 8.9092766e-06 | Z4: -1.5545961e-06 | AA4: 3.4846523e-07 | AB4: 9.6370427e-07 | AC4: 4.9853983e-07 | AD4: 8.3669657e-07 | AE4: 5.8390579e-07 | AF4: -9.6135342e-08 | AG4: -8.0639143e-07 | AH4: -1.2564622e-07 | AI4: -2.3204536e-06 | AJ4: -2.4578745e-06 | AK4: -2.5931505e-07 | AL4: 3.9590799e-07 | AM4: 4.9511357e-07 | AN4: 3.5687115e-07 | AO4: -6.7379393e-06 | AP4: -2.1148259e-06 | AQ4: -0.00015701557
A5: Dag_sq | B5: 0.00023304201 | C5: -1.1376512e-07 | D5: -2.243003e-08 | E5: -6.7980001e-08 | F5: 6.7981971e-10 | G5: 7.5750407e-10 | H5: -6.3406456e-10 | I5: 4.5436295e-09 | J5: 1.5078994e-08 | K5: 1.4617842e-08 | L5: 4.2669648e-09 | M5: 2.845948e-08 | N5: -2.5353771e-09 | O5: 3.7536319e-10 | P5: 1.5669617e-08 | Q5: -7.4931651e-09 | R5: -5.834791e-08 | S5: -8.6718454e-09 | T5: -9.6323541e-08 | U5: 1.7157724e-07 | V5: -2.7239495e-08 | W5: -1.6466297e-08 | X5: -1.2477903e-07 | Y5: -5.0291489e-08 | Z5: 1.3240509e-08 | AA5: -9.5558987e-11 | AB5: -5.601192e-09 | AC5: -6.8625414e-10 | AD5: -4.3068129e-09 | AE5: -5.2950621e-09 | AF5: 1.7991213e-09 | AG5: 3.0691216e-09 | AH5: -2.1816307e-09 | AI5: 2.1199969e-08 | AJ5: 1.633282e-08 | AK5: 8.8507984e-10 | AL5: -6.1246716e-09 | AM5: -8.3301074e-09 | AN5: 1.3231325e-08 | AO5: 5.0052533e-08 | AP5: 1.8985558e-08 | AQ5: 1.3581346e-06
A6: Dhe_pcs_L1 | B6: 0.012631804 | C6: 1.6855851e-06 | D6: -2.8477599e-07 | E6: 4.0355518e-08 | F6: 7.5750407e-10 | G6: 6.1042652e-07 | H6: 1.4423511e-09 | I6: -7.1980909e-08 | J6: -1.0702691e-07 | K6: -1.6326251e-07 | L6: -7.6820801e-08 | M6: -2.9793654e-07 | N6: -1.9223012e-07 | O6: 1.7438813e-07 | P6: 1.4750598e-07 | Q6: 4.3694213e-08 | R6: 1.7976791e-06 | S6: 1.0342041e-06 | T6: -3.2664791e-07 | U6: 1.1344675e-06 | V6: -4.76193e-07 | W6: 1.5898012e-07 | X6: 5.1253062e-07 | Y6: 6.2787073e-07 | Z6: 4.0309043e-07 | AA6: 7.322512e-07 | AB6: 9.721563e-07 | AC6: 7.6287224e-07 | AD6: 7.0061154e-07 | AE6: 3.8823775e-07 | AF6: -3.3776981e-07 | AG6: 2.3554076e-07 | AH6: 9.2887172e-07 | AI6: 5.430624e-07 | AJ6: 7.8911259e-07 | AK6: 1.5413711e-08 | AL6: 6.6669222e-08 | AM6: -2.446951e-07 | AN6: 1.6184589e-06 | AO6: -6.2334911e-07 | AP6: -4.0754568e-07 | AQ6: -3.5052312e-05
A7: Dhe_mcs_L1 | B7: 0.0052351586 | C7: -1.4793555e-08 | D7: -9.372536e-07 | E7: 2.9378808e-08 | F7: -6.3406456e-10 | G7: 1.4423511e-09 | H7: 6.0876462e-07 | I7: -5.0359569e-08 | J7: -6.3400724e-08 | K7: -2.9845652e-08 | L7: -1.0144017e-07 | M7: 7.3201838e-07 | N7: 3.3470041e-07 | O7: -4.3650896e-07 | P7: 9.0459599e-08 | Q7: 1.7898864e-07 | R7: 4.0198823e-08 | S7: -2.7997055e-07 | T7: 1.1192346e-06 | U7: 2.5517758e-06 | V7: -9.4416183e-07 | W7: 5.3700113e-10 | X7: 7.322587e-07 | Y7: 1.525415e-06 | Z7: 5.2327896e-07 | AA7: 2.5450904e-07 | AB7: -3.9829252e-08 | AC7: -7.1370331e-08 | AD7: 3.6730069e-07 | AE7: 3.5085485e-08 | AF7: 2.4351786e-08 | AG7: 2.0164206e-07 | AH7: 3.8092464e-07 | AI7: -2.4718677e-07 | AJ7: 5.5865643e-08 | AK7: 1.1797342e-07 | AL7: 5.6121651e-07 | AM7: 4.3023389e-07 | AN7: -4.7119653e-07 | AO7: -1.2689233e-06 | AP7: 1.3255535e-07 | AQ7: -3.0952883e-05
A8: Ypncp_L1 | B8: 0.35965781 | C8: 1.9212086e-06 | D8: -2.3937803e-06 | E8: -6.2259647e-07 | F8: 4.5436295e-09 | G8: -7.1980909e-08 | H8: -5.0359569e-08 | I8: 1.1996197e-05 | J8: -2.1635128e-08 | K8: -6.3424973e-08 | L8: -1.4334737e-06 | M8: 2.2936959e-06 | N8: 1.558167e-07 | O8: 9.273777e-08 | P8: -1.1674207e-05 | Q8: 6.9302771e-07 | R8: 3.1835136e-06 | S8: 1.4148469e-06 | T8: -8.6095567e-06 | U8: 7.8155431e-07 | V8: -5.335854e-06 | W8: 1.3650468e-06 | X8: 4.6657383e-08 | Y8: -1.0066103e-05 | Z8: -6.1015386e-07 | AA8: -2.482286e-06 | AB8: -1.666601e-06 | AC8: -8.9009357e-07 | AD8: -2.4152703e-06 | AE8: -8.7829518e-07 | AF8: -8.2109044e-07 | AG8: -2.0789956e-06 | AH8: -7.7537425e-07 | AI8: -8.0196696e-07 | AJ8: -8.938726e-07 | AK8: 2.7364532e-07 | AL8: -6.4925914e-08 | AM8: -1.5147744e-06 | AN8: -2.7700145e-06 | AO8: 1.7016177e-06 | AP8: -1.4628912e-06 | AQ8: 8.1090863e-06
A9: Yplgrs_dv_L1 | B9: 0.070213024 | C9: 1.5108493e-05 | D9: -3.0704306e-05 | E9: -1.9567822e-06 | F9: 1.5078994e-08 | G9: -1.0702691e-07 | H9: -6.3400724e-08 | I9: -2.1635128e-08 | J9: 0.00016087652 | K9: -9.5945859e-06 | L9: -3.6080448e-07 | M9: 3.2179731e-05 | N9: -1.9053076e-07 | O9: -1.2441413e-07 | P9: 6.87542e-07 | Q9: -6.8617768e-07 | R9: 4.6752601e-05 | S9: 4.2618846e-05 | T9: 0.0012148532 | U9: 0.0012219435 | V9: 0.0012164289 | W9: -1.729956e-05 | X9: 2.7163128e-06 | Y9: 1.648646e-05 | Z9: 2.3761205e-05 | AA9: 2.5189476e-05 | AB9: 2.4911755e-05 | AC9: 2.6615448e-05 | AD9: 1.8708319e-05 | AE9: 1.7843591e-05 | AF9: 1.818127e-05 | AG9: 3.4587133e-05 | AH9: 2.7140886e-05 | AI9: 1.8037605e-05 | AJ9: 2.8053739e-05 | AK9: -1.969932e-07 | AL9: 4.4495975e-06 | AM9: 1.0039154e-06 | AN9: 1.1737307e-05 | AO9: 1.5085727e-05 | AP9: -3.1900613e-06 | AQ9: -0.001191584
A10: Yplgrs_dv_L2 | B10: 0.028579125 | C10: 7.4411552e-07 | D10: -1.9048571e-06 | E10: -1.7064951e-06 | F10: 1.4617842e-08 | G10: -1.6326251e-07 | H10: -2.9845652e-08 | I10: -6.3424973e-08 | J10: -9.5945859e-06 | K10: 1.267374e-05 | L10: 3.0848113e-08 | M10: 1.6315812e-06 | N10: 4.0761308e-07 | O10: -2.436579e-08 | P10: -5.8375744e-07 | Q10: 4.6667542e-06 | R10: 5.9099391e-06 | S10: 2.727911e-06 | T10: -2.4431757e-05 | U10: -1.4867172e-05 | V10: 1.1284911e-05 | W10: -9.8993823e-07 | X10: 2.5335331e-06 | Y10: 5.4825842e-06 | Z10: -2.2594283e-07 | AA10: 1.8038923e-08 | AB10: 9.4711691e-07 | AC10: 5.7845817e-07 | AD10: 9.6692215e-08 | AE10: -5.6366009e-07 | AF10: -1.2217771e-07 | AG10: 8.4107439e-07 | AH10: 4.7879081e-08 | AI10: -1.9017495e-07 | AJ10: 2.2866123e-06 | AK10: -4.6703828e-08 | AL10: -1.7788727e-06 | AM10: -5.6439624e-07 | AN10: 3.5407737e-06 | AO10: 3.5242081e-06 | AP10: 5.7165652e-06 | AQ10: 3.569594e-05
A11: Ypncp_L2 | B11: 0.24175926 | C11: 1.7812894e-06 | D11: -2.7785158e-06 | E11: -6.8573772e-07 | F11: 4.2669648e-09 | G11: -7.6820801e-08 | H11: -1.0144017e-07 | I11: -1.4334737e-06 | J11: -3.6080448e-07 | K11: 3.0848113e-08 | L11: 1.1922799e-05 | M11: 3.4987681e-06 | N11: 2.5934387e-08 | O11: 5.3072635e-08 | P11: 1.4339402e-06 | Q11: -1.1609785e-05 | R11: 9.5259847e-06 | S11: 4.9305126e-06 | T11: -2.7521106e-06 | U11: -3.0889657e-06 | V11: -8.170448e-06 | W11: 1.6035054e-06 | X11: 1.8466097e-06 | Y11: -8.7283348e-06 | Z11: 4.2184133e-06 | AA11: 1.9464843e-06 | AB11: 2.0439802e-06 | AC11: 3.6443198e-06 | AD11: 1.3408309e-06 | AE11: 2.0449793e-06 | AF11: 1.5514435e-06 | AG11: 3.2023996e-07 | AH11: 2.7589314e-06 | AI11: 2.4082997e-06 | AJ11: 5.0024728e-06 | AK11: 8.495546e-08 | AL11: -1.9086667e-06 | AM11: -1.4958463e-06 | AN11: 1.4193827e-06 | AO11: 1.0915318e-05 | AP11: 6.2371581e-06 | AQ11: 1.2472996e-05
A12: Ded_Dgn | B12: 0.15881231 | C12: -0.002124984 | D12: -0.00024540017 | E12: -3.3013538e-06 | F12: 2.845948e-08 | G12: -2.9793654e-07 | H12: 7.3201838e-07 | I12: 2.2936959e-06 | J12: 3.2179731e-05 | K12: 1.6315812e-06 | L12: 3.4987681e-06 | M12: 0.0046802596 | N12: 1.3757259e-05 | O12: -1.9136859e-05 | P12: -6.5469501e-05 | Q12: 2.4307637e-06 | R12: 9.3834984e-06 | S12: 1.5203681e-05 | T12: 0.0002813798 | U12: 0.00023690777 | V12: 0.00023491318 | W12: -9.5068244e-06 | X12: -2.1216916e-05 | Y12: -1.2570992e-05 | Z12: 0.0001067076 | AA12: 4.7168489e-05 | AB12: 5.577655e-05 | AC12: 5.4915695e-05 | AD12: 7.4496186e-05 | AE12: 7.9942688e-05 | AF12: 3.0729973e-05 | AG12: 5.0772922e-05 | AH12: 5.9783751e-05 | AI12: 6.3396208e-05 | AJ12: 7.4892458e-05 | AK12: 1.6432462e-06 | AL12: -1.9477943e-05 | AM12: -1.4101474e-05 | AN12: 4.7051044e-06 | AO12: 5.40901e-05 | AP12: 5.2764355e-06 | AQ12: -0.00016917436
A13: Ded_Dhe_pcs_L1 | B13: 0.0060994171 | C13: -3.744376e-05 | D13: -2.2482876e-07 | E13: 2.308637e-07 | F13: -2.5353771e-09 | G13: -1.9223012e-07 | H13: 3.3470041e-07 | I13: 1.558167e-07 | J13: -1.9053076e-07 | K13: 4.0761308e-07 | L13: 2.5934387e-08 | M13: 1.3757259e-05 | N13: 5.0317657e-06 | O13: -4.3889494e-06 | P13: -2.5814818e-06 | Q13: -1.5223533e-06 | R13: -6.7624605e-07 | S13: -3.6829039e-07 | T13: -3.8802639e-05 | U13: 2.2607737e-06 | V13: 6.0900422e-07 | W13: -7.3361336e-07 | X13: 1.1111924e-06 | Y13: 2.9429771e-07 | Z13: -2.3445737e-07 | AA13: -4.9349294e-07 | AB13: -6.3108981e-07 | AC13: -1.5214711e-06 | AD13: -1.2780145e-06 | AE13: -8.7018536e-07 | AF13: -6.5570019e-07 | AG13: -1.0618184e-06 | AH13: -5.3198758e-07 | AI13: -1.3391942e-06 | AJ13: -4.8230711e-07 | AK13: 1.2236634e-09 | AL13: -8.561806e-07 | AM13: -1.5972726e-07 | AN13: 9.6065853e-07 | AO13: 1.5218147e-07 | AP13: 1.6244912e-06 | AQ13: -1.2158121e-05
... A42: Constant | B42: -2.0859754 | C42: -0.00066964333 | D42: 0.00014698695 | E42: -0.00015701557 | F42: 1.3581346e-06 | G42: -3.5052312e-05 | H42: -3.0952883e-05 | I42: 8.1090863e-06 | J42: -0.001191584 | K42: 3.569594e-05 | L42: 1.2472996e-05 | M42: -0.00016917436 | N42: -1.2158121e-05 | O42: 1.0979623e-05 | P42: 6.6777518e-05 | Q42: -8.5468173e-05 | R42: -0.00077419408 | S42: -0.00062453287 | T42: -0.010417342 | U42: -0.0097518678 | V42: -0.009511494 | W42: -0.0002555798 | X42: -0.000640485 | Y42: -0.00078973286 | Z42: -0.001057417 | AA42: -0.0011253062 | AB42: -0.0011255392 | AC42: -0.0011168146 | AD42: -0.0010691269 | AE42: -0.0010211229 | AF42: -0.0010071927 | AG42: -0.0011403521 | AH42: -0.0011613047 | AI42: -0.00097434082 | AJ42: -0.0010500151 | AK42: -6.376171e-05 | AL42: 0.00014735171 | AM42: 0.00023539744 | AN42: -0.00061505077 | AO42: -0.00042269856 | AP42: -0.00026683182 | AQ42: 0.019581506

Sheet I1b_orig
A1: REGRESSOR | B1: COEFFICIENT | C1: Dgn | D1: Dag | E1: Dag_sq | F1: Deh_c4_Low | G1: Deh_c4_Medium | H1: Deh_c4_High | I1: Les_c4_Student_L1 | J1: Les_c4_NotEmployed_L1 | K1: Les_c4_Retired_L1 | L1: Dhhtp_c4_CoupleChildren_L1 | M1: Dhhtp_c4_SingleNoChildren_L1 | N1: Dhhtp_c4_SingleChildren_L1 | O1: Dhe_pcs_L1 | P1: Dhe_mcs_L1 | Q1: Ypncp_L1 | R1: Ypncp_L2 | S1: Yplgrs_dv_L1 | T1: Yplgrs_dv_L2 | U1: Ded_Dgn | V1: Ded_Ypncp_L1 | W1: Ded_Ypncp_L2 | X1: demRgnUKC | Y1: demRgnUKD | Z1: demRgnUKE | AA1: demRgnUKF | AB1: demRgnUKG | AC1: demRgnUKH | AD1: demRgnUKJ | AE1: demRgnUKK | AF1: demRgnUKL | AG1: demRgnUKM | AH1: demRgnUKN | AI1: Year_transformed | AJ1: Y2020 | AK1: Y2021 | AL1: demEthnC4Asian | AM1: demEthnC4Black | AN1: demEthnC4Other | AO1: Constant
A2: Dgn | B2: 0.16808438 | C2: 0.00029454078 | D2: 4.4004565e-06 | E2: -4.5635843e-08 | F2: -0.00011911476 | G2: -0.0001225186 | H2: -0.00012338593 | I2: -0.00021482989 | J2: -0.00020281174 | K2: -0.00019698112 | L2: 8.189455e-06 | M2: 4.210905e-05 | N2: 0.00012701172 | O2: -1.7497296e-07 | P2: -1.4994566e-06 | Q2: -5.3531955e-06 | R2: -1.5155861e-06 | S2: -2.7620411e-05 | T2: -2.1198306e-06 | U2: -0.00028822878 | V2: -3.9636565e-07 | W2: 1.4174068e-06 | X2: 2.0168199e-05 | Y2: 1.8106942e-05 | Z2: 1.7161597e-05 | AA2: 5.2534763e-06 | AB2: 1.3332783e-05 | AC2: 1.1874644e-05 | AD2: 1.6142469e-05 | AE2: 2.2728646e-05 | AF2: 1.2915046e-05 | AG2: 7.5711529e-06 | AH2: 8.6239035e-06 | AI2: 1.085413e-07 | AJ2: 4.1534306e-06 | AK2: 4.9309226e-06 | AL2: 2.4327964e-06 | AM2: 2.4775077e-05 | AN2: -6.77577e-06 | AO2: 0.00018831704
A3: Dag | B3: 0.035590133 | C3: 4.4004565e-06 | D3: 9.837024e-06 | E3: -8.4458189e-08 | F3: -2.3398e-05 | G3: -2.5823465e-05 | H3: -2.3646766e-05 | I3: 7.4785115e-05 | J3: 2.8969119e-06 | K3: -5.1293566e-06 | L3: 6.5820288e-06 | M3: 1.5519693e-05 | N3: 1.6638717e-05 | O3: -8.6086771e-08 | P3: -6.9108947e-08 | Q3: -1.5363473e-06 | R3: -1.0323995e-06 | S3: 5.5876229e-07 | T3: -1.9061414e-06 | U3: -4.4341956e-06 | V3: -3.5751014e-06 | W3: 3.9842411e-06 | X3: -6.6282882e-06 | Y3: -5.874973e-06 | Z3: -5.2317341e-06 | AA3: -5.2459019e-06 | AB3: -7.4893908e-06 | AC3: -5.1092867e-06 | AD3: -3.1659571e-06 | AE3: -4.9647683e-06 | AF3: -6.0373101e-06 | AG3: -6.8125985e-06 | AH3: -9.7534715e-06 | AI3: 4.8448157e-07 | AJ3: -9.5270189e-08 | AK3: -1.745565e-06 | AL3: -2.0428123e-06 | AM3: -1.363191e-05 | AN3: -4.1273258e-07 | AO3: -0.00022338122
A4: Dag_sq | B4: -0.0002907999 | C4: -4.5635843e-08 | D4: -8.4458189e-08 | E4: 7.7921836e-10 | F4: 1.6534705e-07 | G4: 2.1795683e-07 | H4: 2.1057084e-07 | I4: -5.1179382e-07 | J4: 2.6894651e-08 | K4: -3.4330381e-08 | L4: -2.7472462e-08 | M4: -1.3909825e-07 | N4: -9.6028656e-08 | O4: 2.114843e-09 | P4: 1.8296119e-10 | Q4: 1.2071456e-08 | R4: 6.9027046e-09 | S4: -3.1988844e-10 | T4: 1.7179436e-08 | U4: 4.276153e-08 | V4: 3.1729361e-08 | W4: -2.5907376e-08 | X4: 6.4423761e-08 | Y4: 5.9953066e-08 | Z4: 4.9275921e-08 | AA4: 5.3504512e-08 | AB4: 6.5179826e-08 | AC4: 4.635913e-08 | AD4: 2.7457887e-08 | AE4: 4.2914148e-08 | AF4: 5.6489972e-08 | AG4: 6.1104704e-08 | AH4: 8.7532918e-08 | AI4: -5.5007976e-09 | AJ4: -1.2744289e-09 | AK4: 9.4669185e-09 | AL4: 4.115069e-08 | AM4: 1.0730884e-07 | AN4: 1.799622e-08 | AO4: 1.7124248e-06
A5: Deh_c4_Low | B5: -0.70895009 | C5: -0.00011911476 | D5: -2.3398e-05 | E5: 1.6534705e-07 | F5: 0.011593365 | G5: 0.011187002 | H5: 0.011179966 | I5: 0.0037596649 | J5: -0.00017538669 | K5: -2.2243443e-05 | L5: 0.000133753 | M5: -0.00011898654 | N5: 3.7344988e-05 | O5: 1.2969601e-06 | P5: 8.1910629e-08 | Q5: -8.9935519e-06 | R5: 3.2648476e-06 | S5: 6.8287527e-06 | T5: -1.4881498e-05 | U5: 0.0061385981 | V5: 0.00043530536 | W5: 2.4967899e-05 | X5: -1.6532332e-05 | Y5: -0.00010237413 | Z5: -9.3292311e-05 | AA5: -7.4893096e-05 | AB5: -9.3098104e-05 | AC5: -7.7707326e-05 | AD5: -6.5781507e-05 | AE5: -6.1918234e-05 | AF5: -0.00010445969 | AG5: -5.6450286e-05 | AH5: -6.4224458e-05 | AI5: -1.4854888e-06 | AJ5: 6.7055718e-05 | AK5: 9.6333179e-05 | AL5: 4.0118647e-06 | AM5: 0.00016953965 | AN5: -0.0003506377 | AO5: -0.010333149
A6: Deh_c4_Medium | B6: -0.60464798 | C6: -0.0001225186 | D6: -2.5823465e-05 | E6: 2.1795683e-07 | F6: 0.011187002 | G6: 0.011268293 | H6: 0.011146727 | I6: 0.0037837869 | J6: -0.00011461916 | K6: 1.6447812e-05 | L6: 0.0001296645 | M6: -0.00012041153 | N6: 5.0941384e-05 | O6: 5.0959463e-07 | P6: -4.0553373e-07 | Q6: -1.3814371e-05 | R6: -1.8119194e-06 | S6: 1.1571335e-05 | T6: -1.6205771e-05 | U6: 0.0061462855 | V6: 0.00044083844 | W6: 2.9067749e-05 | X6: -4.8207241e-05 | Y6: -0.0001228133 | Z6: -0.00010352651 | AA6: -7.6489899e-05 | AB6: -0.00010339936 | AC6: -9.13595e-05 | AD6: -9.3680713e-05 | AE6: -8.6507548e-05 | AF6: -0.00011363696 | AG6: -9.0186503e-05 | AH6: -6.7365203e-05 | AI6: -5.2989706e-06 | AJ6: 7.4335602e-05 | AK6: 0.00010104414 | AL6: -3.8695229e-07 | AM6: 0.00018666666 | AN6: -0.00035214724 | AO6: -0.010189412
A7: Deh_c4_High | B7: -0.62013452 | C7: -0.00012338593 | D7: -2.3646766e-05 | E7: 2.1057084e-07 | F7: 0.011179966 | G7: 0.011146727 | H7: 0.011410904 | I7: 0.0035077682 | J7: -0.00042351404 | K7: -0.00034428647 | L7: 0.00011717345 | M7: -0.0001158734 | N7: 0.00010662598 | O7: -6.1178942e-07 | P7: 1.2868873e-08 | Q7: -1.7831e-05 | R7: -3.1891967e-06 | S7: -2.9998963e-05 | T7: -1.9212156e-05 | U7: 0.0061384269 | V7: 0.0004520716 | W7: 2.1136216e-05 | X7: 1.9476798e-05 | Y7: -6.4072474e-05 | Z7: -5.1588508e-05 | AA7: -2.6944413e-05 | AB7: -6.8576755e-05 | AC7: -3.4479356e-05 | AD7: -4.1195156e-05 | AE7: -3.7417058e-05 | AF7: -5.12744e-05 | AG7: -5.6218684e-05 | AH7: -3.7064298e-05 | AI7: -6.0502645e-06 | AJ7: 6.155707e-05 | AK7: 9.8870088e-05 | AL7: -5.0686912e-05 | AM7: 0.00012098201 | AN7: -0.00037352657 | AO7: -0.0099325765
A8: Les_c4_Student_L1 | B8: 0.27701097 | C8: -0.00021482989 | D8: 7.4785115e-05 | E8: -5.1179382e-07 | F8: 0.0037596649 | G8: 0.0037837869 | H8: 0.0035077682 | I8: 0.017202401 | J8: 0.011804283 | K8: 0.01152784 | L8: -6.9201653e-05 | M8: 5.8332554e-05 | N8: 0.00064623219 | O8: -4.2249551e-06 | P8: -1.4311163e-07 | Q8: -1.3100365e-05 | R8: 1.080905e-05 | S8: 0.0014593853 | T8: -1.871912e-05 | U8: 0.00015340025 | V8: -0.00017498391 | W8: -2.5771157e-05 | X8: 0.00017579729 | Y8: 0.00011410156 | Z8: 0.00016782394 | AA8: 0.00015888449 | AB8: 0.00010103416 | AC8: 9.3352121e-05 | AD8: 0.00010738083 | AE8: 0.00022680072 | AF8: 0.00019196769 | AG8: 6.3460905e-05 | AH8: 0.00018134929 | AI8: -5.032126e-06 | AJ8: 3.3201257e-05 | AK8: 2.0761591e-05 | AL8: -2.3263994e-05 | AM8: -0.00019083655 | AN8: -0.0001309394 | AO8: -0.017683391
A9: Les_c4_NotEmployed_L1 | B9: -0.13083018 | C9: -0.00020281174 | D9: 2.8969119e-06 | E9: 2.6894651e-08 | F9: -0.00017538669 | G9: -0.00011461916 | H9: -0.00042351404 | I9: 0.011804283 | J9: 0.013104531 | K9: 0.011596945 | L9: -0.00016739242 | M9: 3.457121e-05 | N9: 0.00034299859 | O9: -2.086535e-06 | P9: 4.1172375e-06 | Q9: -3.3090817e-06 | R9: 9.7786109e-06 | S9: 0.0014556673 | T9: -2.8821942e-05 | U9: 0.0001314781 | V9: -3.2000057e-05 | W9: 5.6714386e-06 | X9: 0.00019331758 | Y9: 0.00021587415 | Z9: 0.00025575935 | AA9: 0.00021726446 | AB9: 0.0002219758 | AC9: 0.0001779865 | AD9: 0.00018726726 | AE9: 0.0003143019 | AF9: 0.00033736866 | AG9: 0.00017265418 | AH9: 0.0002248941 | AI9: -4.8215257e-07 | AJ9: 1.0343885e-05 | AK9: -3.1022375e-05 | AL9: -4.0498898e-05 | AM9: 4.6673868e-05 | AN9: 9.3843159e-05 | AO9: -0.012003185
A10: Les_c4_Retired_L1 | B10: -0.22059529 | C10: -0.00019698112 | D10: -5.1293566e-06 | E10: -3.4330381e-08 | F10: -2.2243443e-05 | G10: 1.6447812e-05 | H10: -0.00034428647 | I10: 0.01152784 | J10: 0.011596945 | K10: 0.012204478 | L10: -5.9192001e-05 | M10: 6.3454762e-05 | N10: 0.00061475654 | O10: -2.8153646e-06 | P10: 3.5604208e-07 | Q10: -3.0180719e-06 | R10: 4.1974053e-06 | S10: 0.0014249646 | T10: 1.3680499e-05 | U10: 0.00015827123 | V10: -3.3566393e-05 | W10: 3.6942815e-05 | X10: 0.0001880195 | Y10: 0.00018757663 | Z10: 0.00026358456 | AA10: 0.00022074243 | AB10: 0.00023373872 | AC10: 0.00020176648 | AD10: 0.00020478697 | AE10: 0.00032140993 | AF10: 0.00026629739 | AG10: 0.00017954093 | AH10: 0.00028241409 | AI10: -6.0177307e-06 | AJ10: 3.5348335e-05 | AK10: 6.1836452e-06 | AL10: 1.8802233e-05 | AM10: 0.00012438655 | AN10: 0.00013694422 | AO10: -0.011389986
A11: Dhhtp_c4_CoupleChildren_L1 | B11: -0.065898543 | C11: 8.189455e-06 | D11: 6.5820288e-06 | E11: -2.7472462e-08 | F11: 0.000133753 | G11: 0.0001296645 | H11: 0.00011717345 | I11: -6.9201653e-05 | J11: -0.00016739242 | K11: -5.9192001e-05 | L11: 0.00071628491 | M11: 0.00012892534 | N11: 0.00025497891 | O11: 5.5296996e-07 | P11: 3.0412605e-07 | Q11: 4.058059e-06 | R11: -1.7939003e-06 | S11: -1.8357519e-05 | T11: -4.2619625e-07 | U11: -5.9359982e-05 | V11: 3.0486475e-05 | W11: 1.6718733e-05 | X11: -2.3135705e-05 | Y11: -1.9404105e-05 | Z11: -8.1011176e-06 | AA11: 3.0914568e-06 | AB11: 4.6540804e-06 | AC11: -3.4379119e-05 | AD11: 1.0339473e-05 | AE11: -5.0954988e-06 | AF11: -5.7782997e-06 | AG11: -1.7236252e-05 | AH11: -2.1328673e-05 | AI11: 2.1577075e-06 | AJ11: -9.3919995e-06 | AK11: -2.7767287e-05 | AL11: -3.8154645e-05 | AM11: 1.6349338e-05 | AN11: -3.6571822e-07 | AO11: -0.00053264472
A12: Dhhtp_c4_SingleNoChildren_L1 | B12: -0.019230616 | C12: 4.210905e-05 | D12: 1.5519693e-05 | E12: -1.3909825e-07 | F12: -0.00011898654 | G12: -0.00012041153 | H12: -0.0001158734 | I12: 5.8332554e-05 | J12: 3.457121e-05 | K12: 6.3454762e-05 | L12: 0.00012892534 | M12: 0.0003734161 | N12: 0.00018049813 | O12: 4.1399632e-08 | P12: 8.3092952e-07 | Q12: -3.4030673e-07 | R12: -3.8446344e-07 | S12: 2.4842222e-06 | T12: 1.2423803e-06 | U12: -3.583575e-05 | V12: -2.4746184e-05 | W12: -5.1158104e-06 | X12: -8.2837118e-06 | Y12: 1.0860985e-05 | Z12: 2.7258272e-05 | AA12: 1.604471e-05 | AB12: 2.5060981e-05 | AC12: 1.4099501e-05 | AD12: 1.322356e-05 | AE12: 2.1323494e-05 | AF12: 2.3545037e-05 | AG12: 1.7991398e-06 | AH12: -2.6324055e-05 | AI12: 1.136972e-06 | AJ12: 2.5309674e-06 | AK12: -1.4362918e-05 | AL12: -7.1004308e-06 | AM12: -4.9803773e-05 | AN12: 8.0467285e-06 | AO12: -0.00054347504
A13: Dhhtp_c4_SingleChildren_L1 | B13: 0.73099038 | C13: 0.00012701172 | D13: 1.6638717e-05 | E13: -9.6028656e-08 | F13: 3.7344988e-05 | G13: 5.0941384e-05 | H13: 0.00010662598 | I13: 0.00064623219 | J13: 0.00034299859 | K13: 0.00061475654 | L13: 0.00025497891 | M13: 0.00018049813 | N13: 0.00186334 | O13: 1.282694e-06 | P13: 3.8860695e-06 | Q13: -2.1072429e-05 | R13: -1.4658736e-05 | S13: 5.4105567e-05 | T13: 1.011895e-05 | U13: -3.6291729e-05 | V13: 1.245402e-05 | W13: 5.0242081e-05 | X13: -5.9407096e-07 | Y13: 2.0043511e-05 | Z13: -1.2439839e-05 | AA13: 8.9544528e-06 | AB13: -1.0339314e-05 | AC13: 3.2681019e-06 | AD13: 1.24593e-05 | AE13: 3.2324594e-05 | AF13: 3.5356183e-05 | AG13: -2.5647707e-05 | AH13: -1.3492362e-06 | AI13: 1.2914631e-06 | AJ13: -7.721498e-06 | AK13: -3.5906921e-05 | AL13: 2.1437156e-05 | AM13: -0.00023346176 | AN13: 2.1494954e-05 | AO13: -0.0016351912
... A40: Constant | B40: 2.0575397 | C40: 0.00018831704 | D40: -0.00022338122 | E40: 1.7124248e-06 | F40: -0.010333149 | G40: -0.010189412 | H40: -0.0099325765 | I40: -0.017683391 | J40: -0.012003185 | K40: -0.011389986 | L40: -0.00053264472 | M40: -0.00054347504 | N40: -0.0016351912 | O40: -3.4412329e-05 | P40: -3.9414065e-05 | Q40: 3.904896e-05 | R40: 2.3679076e-05 | S40: -0.0014532554 | T40: 4.3550606e-05 | U40: -0.0061314241 | V40: -0.00018628683 | W40: -0.00025793828 | X40: -0.0013249923 | Y40: -0.0011676907 | Z40: -0.0012297017 | AA40: -0.0012379771 | AB40: -0.0011062674 | AC40: -0.001131924 | AD40: -0.0012376484 | AE40: -0.0012954496 | AF40: -0.0013378076 | AG40: -0.0011188034 | AH40: -0.0011505489 | AI40: -7.2298077e-05 | AJ40: 7.6580545e-05 | AK40: 0.00023022956 | AL40: -0.00065668276 | AM40: -0.00034083579 | AN40: -0.0002386503 | AO40: 0.034450405

Sheet I2b_orig
A1: REGRESSOR | B1: COEFFICIENT | C1: Dgn | D1: Dag | E1: Deh_c4_High | F1: Deh_c4_Medium | G1: Dhhtp_c4_CoupleChildren_L1 | H1: Dhhtp_c4_SingleNoChildren_L1 | I1: Dhhtp_c4_SingleChildren_L1 | J1: Dhe_pcs_L1 | K1: Dhe_mcs_L1 | L1: Ypnoab_L1 | M1: Ypnoab_L2 | N1: demRgnUKC | O1: demRgnUKD | P1: demRgnUKE | Q1: demRgnUKF | R1: demRgnUKG | S1: demRgnUKH | T1: demRgnUKJ | U1: demRgnUKK | V1: demRgnUKL | W1: demRgnUKM | X1: demRgnUKN | Y1: Year_transformed | Z1: Y2020 | AA1: Y2021 | AB1: demEthnC4Asian | AC1: demEthnC4Black | AD1: demEthnC4Other | AE1: Constant
A2: Dgn | B2: 0.26086921 | C2: 0.00028796859 | D2: -2.4019676e-06 | E2: 2.719027e-05 | F2: 2.0446063e-05 | G2: -4.4027173e-05 | H2: 9.8669527e-05 | I2: 4.6108004e-05 | J2: -3.9199335e-07 | K2: -1.4853043e-07 | L2: -2.2752548e-05 | M2: -6.7636612e-06 | N2: -3.2231898e-05 | O2: -1.4750395e-05 | P2: 5.4361958e-06 | Q2: 1.3791973e-05 | R2: -3.7300652e-05 | S2: -2.9787806e-05 | T2: 7.1187079e-06 | U2: -1.6823096e-05 | V2: -6.1341066e-06 | W2: -1.0221752e-05 | X2: -2.2769174e-05 | Y2: 3.0641071e-06 | Z2: 1.0344347e-05 | AA2: 9.9601563e-06 | AB2: -3.7640973e-05 | AC2: 5.2110358e-05 | AD2: -2.0209368e-05 | AE2: 0.000158696
A3: Dag | B3: -0.010083303 | C3: -2.4019676e-06 | D3: 1.0525528e-06 | E3: 5.2894092e-06 | F3: 4.2229919e-06 | G3: 6.2644791e-06 | H3: -4.5258154e-06 | I3: 4.2419944e-06 | J3: 1.3233797e-07 | K3: -3.6306398e-08 | L3: 4.8024781e-07 | M3: -1.9976579e-07 | N3: 3.7703182e-06 | O3: 2.5580552e-06 | P3: 1.7452053e-06 | Q3: 1.54398e-06 | R3: 1.861737e-06 | S3: 1.6749424e-06 | T3: 1.4476082e-06 | U3: 2.0313025e-06 | V3: 1.5061857e-06 | W3: 2.1262058e-06 | X3: 2.2020491e-06 | Y3: -4.5337533e-07 | Z3: 1.872576e-07 | AA3: -4.6021122e-07 | AB3: 2.4411878e-06 | AC3: 2.1930899e-06 | AD3: 2.2742758e-06 | AE3: -7.6796685e-05
A4: Deh_c4_High | B4: 0.62675371 | C4: 2.719027e-05 | D4: 5.2894092e-06 | E4: 0.00059526831 | F4: 0.00030988547 | G4: 7.5555016e-06 | H4: 4.6926162e-05 | I4: 5.0330867e-05 | J4: -1.1004209e-06 | K4: -1.0285379e-07 | L4: -5.7110263e-05 | M4: -1.8635508e-05 | N4: -3.7940232e-05 | O4: -5.3039918e-06 | P4: -3.9337543e-05 | Q4: -3.995991e-05 | R4: -2.0202644e-05 | S4: -2.1113567e-05 | T4: 8.1430609e-06 | U4: 1.3637526e-05 | V4: 2.6775406e-05 | W4: -3.8851576e-05 | X4: -1.8466407e-05 | Y4: -6.3721009e-06 | Z4: 2.1453541e-05 | AA4: -1.7834687e-06 | AB4: -9.1342549e-05 | AC4: 8.6703169e-05 | AD4: -0.0001155026 | AE4: -9.0060309e-06
A5: Deh_c4_Medium | B5: 0.27465082 | C5: 2.0446063e-05 | D5: 4.2229919e-06 | E5: 0.00030988547 | F5: 0.00041428073 | G5: -2.0504963e-05 | H5: 2.5541214e-05 | I5: -1.9114649e-05 | J5: -8.4338512e-07 | K5: -5.8395981e-07 | L5: -3.1115304e-05 | M5: -1.1742932e-05 | N5: -7.6564414e-05 | O5: -5.1039502e-05 | P5: -5.8214405e-05 | Q5: -6.0431453e-05 | R5: -4.6432843e-05 | S5: -6.0722567e-05 | T5: -5.5795219e-05 | U5: -4.9056675e-05 | V5: -5.9353184e-05 | W5: -8.4179073e-05 | X5: -4.9768091e-05 | Y5: -5.1757623e-06 | Z5: 1.1339523e-05 | AA5: 3.7964306e-06 | AB5: -2.1842702e-05 | AC5: -4.6155373e-06 | AD5: -8.8162746e-05 | AE5: -8.0648321e-05
A6: Dhhtp_c4_CoupleChildren_L1 | B6: 0.046534826 | C6: -4.4027173e-05 | D6: 6.2644791e-06 | E6: 7.5555016e-06 | F6: -2.0504963e-05 | G6: 0.0090140103 | H6: 4.6602198e-05 | I6: 0.00024797011 | J6: 1.6639571e-06 | K6: -2.0451247e-07 | L6: 2.3948356e-05 | M6: 9.7326798e-06 | N6: 0.00019920117 | O6: 0.00018814484 | P6: 0.00016349446 | Q6: 9.4327487e-05 | R6: 0.00032150919 | S6: 0.00015188229 | T6: 0.00012509811 | U6: 0.00016503523 | V6: 0.00015361062 | W6: 0.00014818915 | X6: 0.00012742385 | Y6: -2.9645346e-06 | Z6: 4.6195275e-05 | AA6: -2.9906268e-05 | AB6: -0.00019853635 | AC6: -8.6536497e-05 | AD6: 0.00010922264 | AE6: -0.00087994526
A7: Dhhtp_c4_SingleNoChildren_L1 | B7: 0.013678859 | C7: 9.8669527e-05 | D7: -4.5258154e-06 | E7: 4.6926162e-05 | F7: 2.5541214e-05 | G7: 4.6602198e-05 | H7: 0.00031287358 | I7: 0.00012170285 | J7: 5.3451833e-07 | K7: 5.3259489e-07 | L7: -2.1788806e-06 | M7: -9.9936254e-09 | N7: 1.9871701e-05 | O7: 1.2512913e-05 | P7: 4.4227474e-05 | Q7: 3.6672541e-05 | R7: 1.6036758e-05 | S7: 2.660194e-05 | T7: 3.4621227e-05 | U7: 1.7882683e-05 | V7: 1.112401e-05 | W7: 7.395833e-06 | X7: -1.2848278e-06 | Y7: 1.6755995e-06 | Z7: 9.19563e-06 | AA7: 9.1421768e-06 | AB7: 1.7614117e-05 | AC7: -4.1056805e-06 | AD7: 1.0101719e-05 | AE7: 5.5368629e-05
A8: Dhhtp_c4_SingleChildren_L1 | B8: 0.12488022 | C8: 4.6108004e-05 | D8: 4.2419944e-06 | E8: 5.0330867e-05 | F8: -1.9114649e-05 | G8: 0.00024797011 | H8: 0.00012170285 | I8: 0.011746537 | J8: 2.6276498e-06 | K8: 1.1850029e-06 | L8: 4.9387202e-06 | M8: 6.0747616e-06 | N8: 0.00026691784 | O8: 0.00019786161 | P8: 0.00023131124 | Q8: 0.00025386713 | R8: 0.00023356087 | S8: 0.00019087509 | T8: 0.00022957269 | U8: 0.00023032339 | V8: 0.00018045664 | W8: 0.00021992358 | X8: 0.00021423488 | Y8: -3.5306479e-06 | Z8: 7.0920523e-06 | AA8: 2.318043e-05 | AB8: -0.00010919632 | AC8: -6.2871497e-05 | AD8: 7.7949605e-05 | AE8: -0.00084233225
A9: Dhe_pcs_L1 | B9: 0.0062493874 | C9: -3.9199335e-07 | D9: 1.3233797e-07 | E9: -1.1004209e-06 | F9: -8.4338512e-07 | G9: 1.6639571e-06 | H9: 5.3451833e-07 | I9: 2.6276498e-06 | J9: 4.1060976e-07 | K9: 4.5780314e-08 | L9: -2.0915702e-07 | M9: -1.7937891e-08 | N9: 3.8276013e-06 | O9: 1.8539034e-06 | P9: 1.7760177e-06 | Q9: 1.1183142e-06 | R9: 2.2784693e-06 | S9: 1.6481604e-06 | T9: 1.2180893e-06 | U9: 1.5888114e-06 | V9: 7.5643608e-07 | W9: 1.2879421e-06 | X9: 2.0073606e-06 | Y9: -2.4732758e-08 | Z9: 1.1814114e-08 | AA9: -2.2816622e-07 | AB9: 2.4238787e-06 | AC9: -6.2531527e-08 | AD9: 1.8051533e-06 | AE9: -2.9571671e-05
A10: Dhe_mcs_L1 | B10: 0.00308013 | C10: -1.4853043e-07 | D10: -3.6306398e-08 | E10: -1.0285379e-07 | F10: -5.8395981e-07 | G10: -2.0451247e-07 | H10: 5.3259489e-07 | I10: 1.1850029e-06 | J10: 4.5780314e-08 | K10: 5.6576401e-07 | L10: -4.7066403e-07 | M10: -1.3193966e-07 | N10: 1.5114649e-06 | O10: 5.8418628e-07 | P10: 7.3791395e-07 | Q10: -1.3578295e-06 | R10: 2.8778081e-07 | S10: -7.8645212e-07 | T10: 5.930058e-07 | U10: 1.0844203e-06 | V10: -1.6471155e-07 | W10: -1.6429608e-06 | X10: -5.7234564e-08 | Y10: 1.8663534e-07 | Z10: -9.4379305e-09 | AA10: -3.201075e-07 | AB10: 2.0887473e-06 | AC10: -1.1347377e-07 | AD10: 1.4222276e-06 | AE10: -2.7947113e-05
A11: Ypnoab_L1 | B11: 0.25503875 | C11: -2.2752548e-05 | D11: 4.8024781e-07 | E11: -5.7110263e-05 | F11: -3.1115304e-05 | G11: 2.3948356e-05 | H11: -2.1788806e-06 | I11: 4.9387202e-06 | J11: -2.0915702e-07 | K11: -4.7066403e-07 | L11: 4.2541427e-05 | M11: 6.633948e-07 | N11: 2.2577187e-05 | O11: 2.7982647e-05 | P11: 2.9761145e-05 | Q11: 2.4541849e-05 | R11: 2.1316325e-05 | S11: 2.850218e-05 | T11: 1.9186959e-05 | U11: 2.0276557e-05 | V11: 2.6419159e-05 | W11: 2.4719157e-05 | X11: 3.8220465e-05 | Y11: -2.1131993e-06 | Z11: -1.0983731e-06 | AA11: 1.6295404e-06 | AB11: 3.0688159e-05 | AC11: 3.2943959e-05 | AD11: 2.4849572e-05 | AE11: -0.00024909435
A12: Ypnoab_L2 | B12: 0.1042284 | C12: -6.7636612e-06 | D12: -1.9976579e-07 | E12: -1.8635508e-05 | F12: -1.1742932e-05 | G12: 9.7326798e-06 | H12: -9.9936254e-09 | I12: 6.0747616e-06 | J12: -1.7937891e-08 | K12: -1.3193966e-07 | L12: 6.633948e-07 | M12: 1.4094606e-05 | N12: 2.0899566e-06 | O12: 3.6845691e-06 | P12: 5.9064787e-06 | Q12: 1.9691785e-06 | R12: 8.0941748e-06 | S12: 8.3220063e-06 | T12: 3.6500391e-06 | U12: 4.4058273e-07 | V12: 8.5045626e-06 | W12: 7.3756466e-06 | X12: 1.1137224e-05 | Y12: -4.303796e-07 | Z12: -2.7557368e-06 | AA12: -2.3709585e-06 | AB12: 1.239704e-05 | AC12: 9.8231149e-06 | AD12: 1.1495e-05 | AE12: -6.1506506e-05
A13: demRgnUKC | B13: -0.10294962 | C13: -3.2231898e-05 | D13: 3.7703182e-06 | E13: -3.7940232e-05 | F13: -7.6564414e-05 | G13: 0.00019920117 | H13: 1.9871701e-05 | I13: 0.00026691784 | J13: 3.8276013e-06 | K13: 1.5114649e-06 | L13: 2.2577187e-05 | M13: 2.0899566e-06 | N13: 0.0029650583 | O13: 0.0014490889 | P13: 0.001435714 | Q13: 0.0014358031 | R13: 0.0014274074 | S13: 0.0014228371 | T13: 0.0014280614 | U13: 0.0014453877 | V13: 0.0014399964 | W13: 0.001441242 | X13: 0.0014454557 | Y13: -4.9705804e-06 | Z13: 1.9909628e-06 | AA13: -5.6649679e-06 | AB13: 0.00065615577 | AC13: 0.00078053636 | AD13: 0.00035348196 | AE13: -0.0019959461
... A30: Constant | B30: 4.3262399 | C30: 0.000158696 | D30: -7.6796685e-05 | E30: -9.0060309e-06 | F30: -8.0648321e-05 | G30: -0.00087994526 | H30: 5.5368629e-05 | I30: -0.00084233225 | J30: -2.9571671e-05 | K30: -2.7947113e-05 | L30: -0.00024909435 | M30: -6.1506506e-05 | N30: -0.0019959461 | O30: -0.0018542974 | P30: -0.0018328757 | Q30: -0.0016301421 | R30: -0.001767188 | S30: -0.0017079059 | T30: -0.0017041793 | U30: -0.0017872304 | V30: -0.0017735249 | W30: -0.0016733535 | X30: -0.0018680562 | Y30: -6.1352905e-06 | Z30: 0.00010129947 | AA30: 0.00018284706 | AB30: -0.0011882453 | AC30: -0.0011482462 | AD30: -0.00087761499 | AE30: 0.012289088

Sheet I3a_orig
A1: REGRESSOR | B1: COEFFICIENT | C1: Dgn | D1: Reached_Retirement_Age | E1: Deh_c4_High | F1: Deh_c4_Medium | G1: Les_c4_NotEmployed_L1 | H1: Dhhtp_c4_CoupleChildren_L1 | I1: Dhhtp_c4_SingleNoChildren_L1 | J1: Dhhtp_c4_SingleChildren_L1 | K1: Dhe_pcs_L1 | L1: Dhe_mcs_L1 | M1: Hourly_wage_L1 | N1: demRgnUKC | O1: demRgnUKD | P1: demRgnUKE | Q1: demRgnUKF | R1: demRgnUKG | S1: demRgnUKH | T1: demRgnUKJ | U1: demRgnUKK | V1: demRgnUKL | W1: demRgnUKM | X1: demRgnUKN | Y1: Year_transformed | Z1: Y2020 | AA1: Y2021 | AB1: demEthnC4Asian | AC1: demEthnC4Black | AD1: demEthnC4Other | AE1: Constant
A2: Dgn | B2: 0.35383796 | C2: 0.0066650443 | D2: 0.00014796695 | E2: 0.0014096413 | F2: 0.00086451884 | G2: 0.00046142078 | H2: -0.0015188093 | I2: 0.0008546271 | J2: 0.00033884372 | K2: 3.6735303e-05 | L2: -1.9138152e-05 | M2: -3.9617751e-05 | N2: 0.00014772123 | O2: -0.00076708561 | P2: -0.00036345525 | Q2: -0.0012996608 | R2: -0.0014385868 | S2: -0.0011264501 | T2: -0.00059741983 | U2: -0.00058240177 | V2: -0.00097035459 | W2: -0.0014659934 | X2: -0.0012112653 | Y2: 0.00011090627 | Z2: -0.00064681664 | AA2: 0.00020169603 | AB2: 0.00037231177 | AC2: 0.00048357832 | AD2: -0.0020186434 | AE2: -0.0053601844
A3: Reached_Retirement_Age | B3: 0.21625282 | C3: 0.00014796695 | D3: 0.0072279169 | E3: 0.0014377996 | F3: 0.0016699542 | G3: 0.0013479871 | H3: 0.001019115 | I3: -0.00056838727 | J3: -0.0012013195 | K3: 5.7541408e-06 | L3: -5.9174423e-05 | M3: 4.8347326e-05 | N3: 0.0029064106 | O3: 0.001285483 | P3: 0.002130785 | Q3: 0.0014210324 | R3: 0.0012580379 | S3: 0.0011508798 | T3: 0.0008580969 | U3: 0.0012867189 | V3: 0.0017986766 | W3: 0.0015612546 | X3: 0.0017701464 | Y3: 0.00010366463 | Z3: 0.00040398948 | AA3: 0.0010420392 | AB3: 2.5217784e-05 | AC3: 0.0024760833 | AD3: -0.00056445788 | AE3: -0.0061648114
A4: Deh_c4_High | B4: 0.7941064 | C4: 0.0014096413 | D4: 0.0014377996 | E4: 0.013747063 | F4: 0.0067119726 | G4: 0.0012573401 | H4: -0.00083549109 | I4: 0.00049667441 | J4: -0.00013027515 | K4: -4.2890632e-05 | L4: -3.3635432e-06 | M4: -9.4084819e-05 | N4: -0.00035906864 | O4: -0.0012381464 | P4: -0.0002025689 | Q4: -0.00093173846 | R4: -0.00075293935 | S4: -0.0014961011 | T4: -0.0012713951 | U4: -0.0010426951 | V4: -0.00040248759 | W4: -0.0012595875 | X4: -0.00038488615 | Y4: -8.0327097e-05 | Z4: 0.00051251636 | AA4: -0.00024636037 | AB4: -0.0016321297 | AC4: 0.00086532558 | AD4: -0.0014580144 | AE4: -0.0028090172
A5: Deh_c4_Medium | B5: 0.60458273 | C5: 0.00086451884 | D5: 0.0016699542 | E5: 0.0067119726 | F5: 0.0094651353 | G5: 0.00054565994 | H5: -0.00010731633 | I5: 1.4187576e-05 | J5: -0.001060964 | K5: -2.5871873e-05 | L5: -3.2082984e-05 | M5: -3.4072951e-05 | N5: -0.00011677393 | O5: -0.00046094353 | P5: -0.00027840969 | Q5: 2.0303399e-05 | R5: -0.000248807 | S5: -0.00038577261 | T5: -0.0009955824 | U5: -0.00060340469 | V5: -0.00026816337 | W5: -0.0005200421 | X5: 0.00029852359 | Y5: -5.1865908e-05 | Z5: -0.00015365799 | AA5: -1.8351524e-05 | AB5: -0.00012114965 | AC5: 0.0001221082 | AD5: -0.001673196 | AE5: -0.0031110007
A6: Les_c4_NotEmployed_L1 | B6: -1.1673515 | C6: 0.00046142078 | D6: 0.0013479871 | E6: 0.0012573401 | F6: 0.00054565994 | G6: 0.010333998 | H6: -3.5356808e-05 | I6: -0.0011588836 | J6: -0.0015868142 | K6: 0.00011975281 | L6: 9.4471121e-05 | M6: 6.5412693e-06 | N6: -0.0011019827 | O6: -0.00077783414 | P6: -0.0011911745 | Q6: -0.00049450682 | R6: -0.00038680277 | S6: -0.00071116422 | T6: -0.00061992646 | U6: -0.00062480277 | V6: -0.00025101502 | W6: -0.0010136201 | X6: -0.00067081185 | Y6: -1.95695e-06 | Z6: 0.00059178247 | AA6: 0.00032814852 | AB6: -0.0017669227 | AC6: -0.00027929567 | AD6: -0.0012533876 | AE6: -0.013622329
A7: Dhhtp_c4_CoupleChildren_L1 | B7: 0.071977454 | C7: -0.0015188093 | D7: 0.001019115 | E7: -0.00083549109 | F7: -0.00010731633 | G7: -3.5356808e-05 | H7: 0.053292958 | I7: 0.0017933573 | J7: 0.0019553707 | K7: -2.7012031e-05 | L7: 3.8377401e-05 | M7: -6.9365727e-06 | N7: 0.0025402372 | O7: 0.002960887 | P7: 0.0024998468 | Q7: 0.0023889798 | R7: 0.0019166357 | S7: 0.0020087589 | T7: 0.0022213671 | U7: 0.0033549028 | V7: 0.0019756601 | W7: 0.0023337129 | X7: 0.0022844993 | Y7: 5.2165e-06 | Z7: 0.00019501763 | AA7: -0.00064688032 | AB7: -0.0050619835 | AC7: 0.0018197576 | AD7: 0.0013009076 | AE7: -0.0044001471
A8: Dhhtp_c4_SingleNoChildren_L1 | B8: 0.028802886 | C8: 0.0008546271 | D8: -0.00056838727 | E8: 0.00049667441 | F8: 1.4187576e-05 | G8: -0.0011588836 | H8: 0.0017933573 | I8: 0.0091823627 | J8: 0.0032380855 | K8: 3.4343536e-05 | L8: 3.1749199e-05 | M8: -8.1743053e-06 | N8: -0.0014358192 | O8: -0.0010680957 | P8: -0.00017956394 | Q8: -0.00067880911 | R8: -0.00032326769 | S8: -0.00062293309 | T8: -0.0008894464 | U8: -0.00065094446 | V8: -0.00055401498 | W8: 0.00015800581 | X8: -0.00062502832 | Y8: 0.00012189515 | Z8: -0.00083827246 | AA8: -0.00071277166 | AB8: 0.001036705 | AC8: -0.0025418086 | AD8: -0.0033907292 | AE8: -0.0067741559
A9: Dhhtp_c4_SingleChildren_L1 | B9: 0.25579166 | C9: 0.00033884372 | D9: -0.0012013195 | E9: -0.00013027515 | F9: -0.001060964 | G9: -0.0015868142 | H9: 0.0019553707 | I9: 0.0032380855 | J9: 0.25291843 | K9: 0.00011007287 | L9: 7.9819378e-05 | M9: 1.070717e-05 | N9: 0.0036442443 | O9: 0.0021426346 | P9: -0.00063999412 | Q9: 0.003201335 | R9: 0.0025502584 | S9: 0.0011231787 | T9: 0.0017339219 | U9: 0.0036023741 | V9: 0.004250106 | W9: 0.0033560423 | X9: 0.0023067351 | Y9: -7.816384e-05 | Z9: 0.0017157079 | AA9: 0.0011983672 | AB9: -0.0013172228 | AC9: -0.012552229 | AD9: -0.0079892612 | AE9: -0.011163622
A10: Dhe_pcs_L1 | B10: 0.003924723 | C10: 3.6735303e-05 | D10: 5.7541408e-06 | E10: -4.2890632e-05 | F10: -2.5871873e-05 | G10: 0.00011975281 | H10: -2.7012031e-05 | I10: 3.4343536e-05 | J10: 0.00011007287 | K10: 1.5075845e-05 | L10: 1.9952741e-07 | M10: -1.6651409e-06 | N10: 1.1712304e-06 | O10: -2.7321331e-05 | P10: -7.7853134e-05 | Q10: -3.3107361e-05 | R10: -4.8265744e-05 | S10: -3.7245685e-05 | T10: -5.5849834e-05 | U10: -5.1486078e-05 | V10: -1.0747032e-05 | W10: -5.776218e-05 | X10: -2.8959782e-05 | Y10: -2.043494e-07 | Z10: 8.5490769e-06 | AA10: 1.237366e-05 | AB10: 4.0988381e-05 | AC10: -3.9037846e-05 | AD10: 6.80252e-06 | AE10: -0.00069695972
A11: Dhe_mcs_L1 | B11: 0.0037619527 | C11: -1.9138152e-05 | D11: -5.9174423e-05 | E11: -3.3635432e-06 | F11: -3.2082984e-05 | G11: 9.4471121e-05 | H11: 3.8377401e-05 | I11: 3.1749199e-05 | J11: 7.9819378e-05 | K11: 1.9952741e-07 | L11: 1.9525888e-05 | M11: -3.5846815e-07 | N11: -0.00013475465 | O11: -9.4461063e-05 | P11: -0.00013710539 | Q11: -8.2031912e-05 | R11: -0.00011709481 | S11: -9.4625654e-05 | T11: -9.2513569e-05 | U11: -0.00010271392 | V11: -8.4767327e-05 | W11: -0.0001120044 | X11: -0.00011535534 | Y11: 5.0423044e-06 | Z11: -1.3175476e-05 | AA11: -1.6221572e-05 | AB11: 2.8747868e-06 | AC11: -8.7978968e-05 | AD11: -3.2966207e-05 | AE11: -0.00094813997
A12: Hourly_wage_L1 | B12: 0.0043469926 | C12: -3.9617751e-05 | D12: 4.8347326e-05 | E12: -9.4084819e-05 | F12: -3.4072951e-05 | G12: 6.5412693e-06 | H12: -6.9365727e-06 | I12: -8.1743053e-06 | J12: 1.070717e-05 | K12: -1.6651409e-06 | L12: -3.5846815e-07 | M12: 1.3685351e-05 | N12: 8.3650671e-05 | O12: 6.6038504e-05 | P12: 5.3222709e-05 | Q12: 7.1891035e-05 | R12: 5.0543852e-05 | S12: 5.298738e-05 | T12: 6.6512508e-05 | U12: 6.4755802e-05 | V12: 8.4153005e-05 | W12: 5.2372089e-05 | X12: 7.0874544e-05 | Y12: -2.869398e-07 | Z12: -4.3025179e-06 | AA12: 2.6082449e-05 | AB12: 4.2262001e-05 | AC12: 4.8349785e-05 | AD12: 0.00010374703 | AE12: -0.0001021448
A13: demRgnUKC | B13: 0.059542 | C13: 0.00014772123 | D13: 0.0029064106 | E13: -0.00035906864 | F13: -0.00011677393 | G13: -0.0011019827 | H13: 0.0025402372 | I13: -0.0014358192 | J13: 0.0036442443 | K13: 1.1712304e-06 | L13: -0.00013475465 | M13: 8.3650671e-05 | N13: 0.068957308 | O13: 0.03101044 | P13: 0.030776255 | Q13: 0.031174593 | R13: 0.03038759 | S13: 0.030704907 | T13: 0.031179717 | U13: 0.031228763 | V13: 0.031346957 | W13: 0.031198325 | X13: 0.031464846 | Y13: -0.00021554517 | Z13: 0.0028997792 | AA13: 0.0050295738 | AB13: 0.013859092 | AC13: 0.019323433 | AD13: 0.0083651651 | AE13: -0.02325357
... A30: Constant | B30: -0.056274553 | C30: -0.0053601844 | D30: -0.0061648114 | E30: -0.0028090172 | F30: -0.0031110007 | G30: -0.013622329 | H30: -0.0044001471 | I30: -0.0067741559 | J30: -0.011163622 | K30: -0.00069695972 | L30: -0.00094813997 | M30: -0.0001021448 | N30: -0.02325357 | O30: -0.020344572 | P30: -0.019104687 | Q30: -0.021440599 | R30: -0.020433566 | S30: -0.019456016 | T30: -0.019423829 | U30: -0.020421153 | V30: -0.02262231 | W30: -0.020345821 | X30: -0.020204246 | Y30: -0.0025544131 | Z30: 0.0066973366 | AA30: 0.0081334711 | AB30: -0.016973286 | AC30: -0.012384682 | AD30: 0.00014669745 | AE30: 0.15701977

Sheet I3b_orig
A1: REGRESSOR | B1: COEFFICIENT | C1: Dgn | D1: Dag | E1: Deh_c4_High | F1: Deh_c4_Medium | G1: Les_c4_NotEmployed_L1 | H1: Dhhtp_c4_CoupleChildren_L1 | I1: Dhhtp_c4_SingleNoChildren_L1 | J1: Dhhtp_c4_SingleChildren_L1 | K1: Dhe_pcs_L1 | L1: Dhe_mcs_L1 | M1: Hourly_wage_L1 | N1: demRgnUKC | O1: demRgnUKD | P1: demRgnUKE | Q1: demRgnUKF | R1: demRgnUKG | S1: demRgnUKH | T1: demRgnUKJ | U1: demRgnUKK | V1: demRgnUKL | W1: demRgnUKM | X1: demRgnUKN | Y1: Year_transformed | Z1: Y2020 | AA1: Y2021 | AB1: demEthnC4Asian | AC1: demEthnC4Black | AD1: demEthnC4Other | AE1: Constant
A2: Dgn | B2: 0.44711177 | C2: 0.0019956266 | D2: -2.4038376e-05 | E2: 0.00044517558 | F2: 0.00045608708 | G2: 0.00043841687 | H2: -0.0003439412 | I2: -1.9133725e-05 | J2: -0.00072020319 | K2: 7.0031464e-06 | L2: -5.8000186e-06 | M2: -1.2135766e-05 | N2: -0.00039290187 | O2: -0.00063920639 | P2: -0.00040329985 | Q2: -0.00051584748 | R2: -0.00071157721 | S2: -0.00065122469 | T2: -0.00039774486 | U2: -0.00038345291 | V2: -0.0005445941 | W2: -0.00055461483 | X2: -0.00056703135 | Y2: 1.7816335e-05 | Z2: -0.00010445153 | AA2: 5.0287387e-05 | AB2: -0.00041801436 | AC2: 8.1763119e-05 | AD2: 0.00048143218 | AE2: 0.00038211064
A3: Dag | B3: -0.059093503 | C3: -2.4038376e-05 | D3: 2.3677734e-05 | E3: 5.6793418e-05 | F3: 4.4458286e-05 | G3: 5.7180497e-05 | H3: 0.00012692154 | I3: -4.6074205e-06 | J3: 8.7351862e-05 | K3: 2.5166143e-07 | L3: -1.2153762e-06 | M3: 1.8892726e-06 | N3: 4.6506838e-05 | O3: 2.7677271e-05 | P3: 5.2835945e-06 | Q3: 7.8008749e-06 | R3: 1.0709454e-05 | S3: 1.8968581e-05 | T3: -2.3899854e-05 | U3: 9.6326773e-06 | V3: 9.4845631e-06 | W3: 3.2453993e-05 | X3: 1.6974801e-05 | Y3: 1.719354e-06 | Z3: 1.9292154e-05 | AA3: 3.6561097e-05 | AB3: 4.958969e-05 | AC3: 8.5234331e-06 | AD3: -6.947478e-05 | AE3: -0.0015378982
A4: Deh_c4_High | B4: 0.86976754 | C4: 0.00044517558 | D4: 5.6793418e-05 | E4: 0.005718721 | F4: 0.0039095418 | G4: 0.00077188116 | H4: 0.00024843141 | I4: 9.2924866e-05 | J4: -8.351781e-05 | K4: -2.0373219e-05 | L4: -1.4455683e-05 | M4: -4.1364615e-05 | N4: -0.00047763363 | O4: -0.0006232398 | P4: 0.00019135359 | Q4: -0.00056577087 | R4: -0.00019326735 | S4: -0.00029172748 | T4: -0.00028367785 | U4: -0.00078596895 | V4: -0.00034602391 | W4: -2.6222408e-05 | X4: -9.8042444e-05 | Y4: -4.1754003e-05 | Z4: 3.0268432e-05 | AA4: -0.00029338967 | AB4: 0.00020258297 | AC4: -0.00028901265 | AD4: -0.00074610736 | AE4: -0.0045173405
A5: Deh_c4_Medium | B5: 0.45277277 | C5: 0.00045608708 | D5: 4.4458286e-05 | E5: 0.0039095418 | F5: 0.0045912896 | G5: 0.00080835614 | H5: 0.00036671039 | I5: 0.00019289669 | J5: -0.00024397089 | K5: -5.0794273e-06 | L5: -5.3327313e-06 | M5: -1.8011347e-05 | N5: -0.00066099853 | O5: -0.00082224754 | P5: -0.00027765189 | Q5: -0.00087812565 | R5: -0.00085946399 | S5: -0.00076089997 | T5: -0.0007185478 | U5: -0.001703377 | V5: -0.00099508972 | W5: -0.00087735447 | X5: -0.00045647184 | Y5: -2.3920127e-05 | Z5: 0.0001909981 | AA5: -0.00022612702 | AB5: -0.00013430614 | AC5: -0.00027021739 | AD5: -0.00062941811 | AE5: -0.0049089278
A6: Les_c4_NotEmployed_L1 | B6: -0.45637809 | C6: 0.00043841687 | D6: 5.7180497e-05 | E6: 0.00077188116 | F6: 0.00080835614 | G6: 0.0056261966 | H6: 0.00073638141 | I6: 6.9088058e-05 | J6: -0.001235886 | K6: 3.5946168e-05 | L6: 6.3552627e-05 | M6: 9.3264492e-06 | N6: -0.00055091781 | O6: -0.00095140726 | P6: -0.00032062293 | Q6: -0.0008302473 | R6: -0.00042660122 | S6: -0.00062427068 | T6: -0.00053456694 | U6: -0.00055035474 | V6: -0.00095393183 | W6: -0.00075045191 | X6: -0.00062417678 | Y6: 6.2510485e-05 | Z6: -0.00022431931 | AA6: -0.00039015499 | AB6: -0.00029847337 | AC6: -0.00026500858 | AD6: -0.0010387211 | AE6: -0.010767648
A7: Dhhtp_c4_CoupleChildren_L1 | B7: -0.14248881 | C7: -0.0003439412 | D7: 0.00012692154 | E7: 0.00024843141 | F7: 0.00036671039 | G7: 0.00073638141 | H7: 0.02197858 | I7: 0.00047439391 | J7: 0.00096097949 | K7: -7.3896795e-06 | L7: 1.6500764e-05 | M7: -1.391576e-05 | N7: 0.00086640696 | O7: 0.0018265681 | P7: 0.00090128488 | Q7: 0.0011543798 | R7: 0.0017477783 | S7: 0.0013752295 | T7: 0.00049919302 | U7: 0.00089578011 | V7: 0.00079999002 | W7: -5.3478563e-05 | X7: 0.00087146783 | Y7: 7.0989934e-06 | Z7: 0.00025170835 | AA7: -0.00073199595 | AB7: 0.00037261808 | AC7: 0.00058979587 | AD7: 0.00026556156 | AE7: -0.010077086
A8: Dhhtp_c4_SingleNoChildren_L1 | B8: 0.027057424 | C8: -1.9133725e-05 | D8: -4.6074205e-06 | E8: 9.2924866e-05 | F8: 0.00019289669 | G8: 6.9088058e-05 | H8: 0.00047439391 | I8: 0.0027931453 | J8: 0.00074881535 | K8: -3.5642613e-06 | L8: 1.0456676e-07 | M8: 1.8125369e-05 | N8: 0.00025941343 | O8: 0.00078392517 | P8: 0.0007108698 | Q8: 0.00074500365 | R8: 0.00084446093 | S8: 0.00035126984 | T8: 0.00070699858 | U8: 0.00058553744 | V8: 0.00083697463 | W8: 0.00050458507 | X8: 0.00046205862 | Y8: 3.0530639e-05 | Z8: -0.0001335213 | AA8: -0.00011858654 | AB8: 0.00023240792 | AC8: 1.772706e-05 | AD8: -5.8379105e-05 | AE8: -0.0016707631
