Workbook

Sheet S2a-comp
A1: =S2a!A1 -> REGRESSOR | B1: =S2a!B1 -> COEFFICIENT | D1: =S2a_orig!A1 -> REGRESSOR | E1: =S2a_orig!B1 -> COEFFICIENT | G1: comp
A2: =S2a!A2 -> careNeedFlagL1 | B2: =S2a!B2 -> 1.6873924 | D2: =S2a_orig!A2 -> NeedCare_L1 | E2: =S2a_orig!B2 -> 1.6873924 | G2: =B2-E2 -> 0
A3: =S2a!A3 -> demMaleFlag | B3: =S2a!B3 -> -0.12684304 | D3: =S2a_orig!A3 -> Dgn | E3: =S2a_orig!B3 -> -0.12684304 | G3: =B3-E3 -> 0
A4: =S2a!A4 -> demAge67to68 | B4: =S2a!B4 -> -0.12345389 | D4: =S2a_orig!A4 -> Age67to68 | E4: =S2a_orig!B4 -> -0.12345389 | G4: =B4-E4 -> 0
A5: =S2a!A5 -> demAge69to70 | B5: =S2a!B5 -> -0.015198448 | D5: =S2a_orig!A5 -> Age69to70 | E5: =S2a_orig!B5 -> -0.015198448 | G5: =B5-E5 -> 0
A6: =S2a!A6 -> demAge71to72 | B6: =S2a!B6 -> 0.02309202 | D6: =S2a_orig!A6 -> Age71to72 | E6: =S2a_orig!B6 -> 0.02309202 | G6: =B6-E6 -> 0
A7: =S2a!A7 -> demAge73to74 | B7: =S2a!B7 -> 0.054451814 | D7: =S2a_orig!A7 -> Age73to74 | E7: =S2a_orig!B7 -> 0.054451814 | G7: =B7-E7 -> 0
A8: =S2a!A8 -> demAge75to76 | B8: =S2a!B8 -> 0.15215825 | D8: =S2a_orig!A8 -> Age75to76 | E8: =S2a_orig!B8 -> 0.15215825 | G8: =B8-E8 -> 0
A9: =S2a!A9 -> demAge77to78 | B9: =S2a!B9 -> 0.19919676 | D9: =S2a_orig!A9 -> Age77to78 | E9: =S2a_orig!B9 -> 0.19919676 | G9: =B9-E9 -> 0
A10: =S2a!A10 -> demAge79to80 | B10: =S2a!B10 -> 0.25040279 | D10: =S2a_orig!A10 -> Age79to80 | E10: =S2a_orig!B10 -> 0.25040279 | G10: =B10-E10 -> 0
A11: =S2a!A11 -> demAge81to82 | B11: =S2a!B11 -> 0.28255827 | D11: =S2a_orig!A11 -> Age81to82 | E11: =S2a_orig!B11 -> 0.28255827 | G11: =B11-E11 -> 0
A12: =S2a!A12 -> demAge83to84 | B12: =S2a!B12 -> 0.35127761 | D12: =S2a_orig!A12 -> Age83to84 | E12: =S2a_orig!B12 -> 0.35127761 | G12: =B12-E12 -> 0
A13: =S2a!A13 -> demAge85plus | B13: =S2a!B13 -> 0.51368692 | D13: =S2a_orig!A13 -> Age85plus | E13: =S2a_orig!B13 -> 0.51368692 | G13: =B13-E13 -> 0
... A37: =S2a!A37 -> Constant | B37: =S2a!B37 -> -0.4408915 | D37: =S2a_orig!A37 -> Constant | E37: =S2a_orig!B37 -> -0.4408915 | G37: =B37-E37 -> 0

Sheet S2b-comp
A1: =S2b!A1 -> REGRESSOR | B1: =S2b!B1 -> COEFFICIENT | D1: =S2b_orig!A1 -> REGRESSOR | E1: =S2b_orig!B1 -> COEFFICIENT | G1: comp
A2: =S2b!A2 -> careReceivedFlagL1 | B2: =S2b!B2 -> 2.2181656 | D2: =S2b_orig!A2 -> ReceiveCare_L1 | E2: =S2b_orig!B2 -> 2.2181656 | G2: =B2-E2 -> 0
A3: =S2b!A3 -> demMaleFlag | B3: =S2b!B3 -> -0.12752691 | D3: =S2b_orig!A3 -> Dgn | E3: =S2b_orig!B3 -> -0.12752691 | G3: =B3-E3 -> 0
A4: =S2b!A4 -> demAge67to68 | B4: =S2b!B4 -> -0.13212939 | D4: =S2b_orig!A4 -> Age67to68 | E4: =S2b_orig!B4 -> -0.13212939 | G4: =B4-E4 -> 0
A5: =S2b!A5 -> demAge69to70 | B5: =S2b!B5 -> -0.050951389 | D5: =S2b_orig!A5 -> Age69to70 | E5: =S2b_orig!B5 -> -0.050951389 | G5: =B5-E5 -> 0
A6: =S2b!A6 -> demAge71to72 | B6: =S2b!B6 -> -0.032245555 | D6: =S2b_orig!A6 -> Age71to72 | E6: =S2b_orig!B6 -> -0.032245555 | G6: =B6-E6 -> 0
A7: =S2b!A7 -> demAge73to74 | B7: =S2b!B7 -> -0.021038734 | D7: =S2b_orig!A7 -> Age73to74 | E7: =S2b_orig!B7 -> -0.021038734 | G7: =B7-E7 -> 0
A8: =S2b!A8 -> demAge75to76 | B8: =S2b!B8 -> 0.11811801 | D8: =S2b_orig!A8 -> Age75to76 | E8: =S2b_orig!B8 -> 0.11811801 | G8: =B8-E8 -> 0
A9: =S2b!A9 -> demAge77to78 | B9: =S2b!B9 -> 0.17611269 | D9: =S2b_orig!A9 -> Age77to78 | E9: =S2b_orig!B9 -> 0.17611269 | G9: =B9-E9 -> 0
A10: =S2b!A10 -> demAge79to80 | B10: =S2b!B10 -> 0.23294455 | D10: =S2b_orig!A10 -> Age79to80 | E10: =S2b_orig!B10 -> 0.23294455 | G10: =B10-E10 -> 0
A11: =S2b!A11 -> demAge81to82 | B11: =S2b!B11 -> 0.30934154 | D11: =S2b_orig!A11 -> Age81to82 | E11: =S2b_orig!B11 -> 0.30934154 | G11: =B11-E11 -> 0
A12: =S2b!A12 -> demAge83to84 | B12: =S2b!B12 -> 0.36060264 | D12: =S2b_orig!A12 -> Age83to84 | E12: =S2b_orig!B12 -> 0.36060264 | G12: =B12-E12 -> 0
A13: =S2b!A13 -> demAge85plus | B13: =S2b!B13 -> 0.53110232 | D13: =S2b_orig!A13 -> Age85plus | E13: =S2b_orig!B13 -> 0.53110232 | G13: =B13-E13 -> 0
... A41: =S2b!A41 -> Constant | B41: =S2b!B41 -> -0.83951647 | D41: =S2b_orig!A41 -> Constant | E41: =S2b_orig!B41 -> -0.83951647 | G41: =B41-E41 -> 0

Sheet S2c-comp
A1: =S2c!A1 -> REGRESSOR | B1: =S2c!B1 -> COEFFICIENT | D1: =S2c_orig!A1 -> REGRESSOR | E1: =S2c_orig!B1 -> COEFFICIENT | G1: comp
A2: =S2c!A2 -> careMarketFormalL1_Mixed | B2: =S2c!B2 -> 1.2882068 | D2: =S2c_orig!A2 -> CareMarketFormal_L1_Mixed | E2: =S2c_orig!B2 -> 1.2882068 | G2: =B2-E2 -> 0
A3: =S2c!A3 -> careMarketInformalL1_Mixed | B3: =S2c!B3 -> -1.2997993 | D3: =S2c_orig!A3 -> CareMarketInformal_L1_Mixed | E3: =S2c_orig!B3 -> -1.2997993 | G3: =B3-E3 -> 0
A4: =S2c!A4 -> careMarketMixedL1_Mixed | B4: =S2c!B4 -> 3.0061834 | D4: =S2c_orig!A4 -> CareMarketMixed_L1_Mixed | E4: =S2c_orig!B4 -> 3.0061834 | G4: =B4-E4 -> 0
A5: =S2c!A5 -> demMaleFlag_Mixed | B5: =S2c!B5 -> -0.1764564 | D5: =S2c_orig!A5 -> Dgn_Mixed | E5: =S2c_orig!B5 -> -0.1764564 | G5: =B5-E5 -> 0
A6: =S2c!A6 -> demAge67to68_Mixed | B6: =S2c!B6 -> -0.33236079 | D6: =S2c_orig!A6 -> Age67to68_Mixed | E6: =S2c_orig!B6 -> -0.33236079 | G6: =B6-E6 -> 0
A7: =S2c!A7 -> demAge69to70_Mixed | B7: =S2c!B7 -> 0.11943924 | D7: =S2c_orig!A7 -> Age69to70_Mixed | E7: =S2c_orig!B7 -> 0.11943924 | G7: =B7-E7 -> 0
A8: =S2c!A8 -> demAge71to72_Mixed | B8: =S2c!B8 -> 0.06841487 | D8: =S2c_orig!A8 -> Age71to72_Mixed | E8: =S2c_orig!B8 -> 0.06841487 | G8: =B8-E8 -> 0
A9: =S2c!A9 -> demAge73to74_Mixed | B9: =S2c!B9 -> 0.17073813 | D9: =S2c_orig!A9 -> Age73to74_Mixed | E9: =S2c_orig!B9 -> 0.17073813 | G9: =B9-E9 -> 0
A10: =S2c!A10 -> demAge75to76_Mixed | B10: =S2c!B10 -> 0.31008172 | D10: =S2c_orig!A10 -> Age75to76_Mixed | E10: =S2c_orig!B10 -> 0.31008172 | G10: =B10-E10 -> 0
A11: =S2c!A11 -> demAge77to78_Mixed | B11: =S2c!B11 -> 0.30640168 | D11: =S2c_orig!A11 -> Age77to78_Mixed | E11: =S2c_orig!B11 -> 0.30640168 | G11: =B11-E11 -> 0
A12: =S2c!A12 -> demAge79to80_Mixed | B12: =S2c!B12 -> 0.16318332 | D12: =S2c_orig!A12 -> Age79to80_Mixed | E12: =S2c_orig!B12 -> 0.16318332 | G12: =B12-E12 -> 0
A13: =S2c!A13 -> demAge81to82_Mixed | B13: =S2c!B13 -> 0.52756958 | D13: =S2c_orig!A13 -> Age81to82_Mixed | E13: =S2c_orig!B13 -> 0.52756958 | G13: =B13-E13 -> 0
... A85: =S2c!A85 -> Constant_Formal | B85: =S2c!B85 -> -0.96075646 | D85: =S2c_orig!A85 -> Constant_Formal | E85: =S2c_orig!B85 -> -0.96075646 | G85: =B85-E85 -> 0

Sheet S2d-comp
A1: =S2d!A1 -> REGRESSOR | B1: =S2d!B1 -> COEFFICIENT | D1: =S2d_orig!A1 -> REGRESSOR | E1: =S2d_orig!B1 -> COEFFICIENT | G1: comp
A2: =S2d!A2 -> careHrsInformalIhsL1 | B2: =S2d!B2 -> 0.17410708 | D2: =S2d_orig!A2 -> HrsReceivedInformalIHS_L1 | E2: =S2d_orig!B2 -> 0.17410708 | G2: =B2-E2 -> 0
A3: =S2d!A3 -> careMarketMixed | B3: =S2d!B3 -> 0.055669602 | D3: =S2d_orig!A3 -> CareMarketMixed | E3: =S2d_orig!B3 -> 0.055669602 | G3: =B3-E3 -> 0
A4: =S2d!A4 -> demMaleFlag | B4: =S2d!B4 -> 0.084035664 | D4: =S2d_orig!A4 -> Dgn | E4: =S2d_orig!B4 -> 0.084035664 | G4: =B4-E4 -> 0
A5: =S2d!A5 -> demAge | B5: =S2d!B5 -> -0.17449011 | D5: =S2d_orig!A5 -> Age | E5: =S2d_orig!B5 -> -0.17449011 | G5: =B5-E5 -> 0
A6: =S2d!A6 -> demAgeSq | B6: =S2d!B6 -> 0.0011387651 | D6: =S2d_orig!A6 -> AgeSquared | E6: =S2d_orig!B6 -> 0.0011387651 | G6: =B6-E6 -> 0
A7: =S2d!A7 -> healthSelfRatedFair | B7: =S2d!B7 -> -0.45901044 | D7: =S2d_orig!A7 -> Dhe_Fair | E7: =S2d_orig!B7 -> -0.45901044 | G7: =B7-E7 -> 0
A8: =S2d!A8 -> healthSelfRatedGood | B8: =S2d!B8 -> -0.53893809 | D8: =S2d_orig!A8 -> Dhe_Good | E8: =S2d_orig!B8 -> -0.53893809 | G8: =B8-E8 -> 0
A9: =S2d!A9 -> healthSelfRatedVeryGood | B9: =S2d!B9 -> -0.80813123 | D9: =S2d_orig!A9 -> Dhe_VeryGood | E9: =S2d_orig!B9 -> -0.80813123 | G9: =B9-E9 -> 0
A10: =S2d!A10 -> healthSelfRatedExcellent | B10: =S2d!B10 -> -0.81179725 | D10: =S2d_orig!A10 -> Dhe_Excellent | E10: =S2d_orig!B10 -> -0.81179725 | G10: =B10-E10 -> 0
A11: =S2d!A11 -> demPartnerStatusPartnered | B11: =S2d!B11 -> 0.3870772 | D11: =S2d_orig!A11 -> Partnered | E11: =S2d_orig!B11 -> 0.3870772 | G11: =B11-E11 -> 0
A12: =S2d!A12 -> eduHighestC4Medium | B12: =S2d!B12 -> 0.018085334 | D12: =S2d_orig!A12 -> Deh_c4_Medium | E12: =S2d_orig!B12 -> 0.018085334 | G12: =B12-E12 -> 0
A13: =S2d!A13 -> eduHighestC4Low | B13: =S2d!B13 -> 0.11722541 | D13: =S2d_orig!A13 -> Deh_c4_Low | E13: =S2d_orig!B13 -> 0.11722541 | G13: =B13-E13 -> 0
... A31: =S2d!A31 -> Constant | B31: =S2d!B31 -> 9.4082342 | D31: =S2d_orig!A31 -> Constant | E31: =S2d_orig!B31 -> 9.4082342 | G31: =B31-E31 -> 0

Sheet S2e-comp
A1: =S2e!A1 -> REGRESSOR | B1: =S2e!B1 -> COEFFICIENT | D1: =S2e_orig!A1 -> REGRESSOR | E1: =S2e_orig!B1 -> COEFFICIENT | G1: comp
A2: =S2e!A2 -> careHrsFormalIhsL1 | B2: =S2e!B2 -> 0.17964493 | D2: =S2e_orig!A2 -> HrsReceivedFormalIHS_L1 | E2: =S2e_orig!B2 -> 0.17964493 | G2: =B2-E2 -> 0
A3: =S2e!A3 -> careMarketMixed | B3: =S2e!B3 -> 0.073019221 | D3: =S2e_orig!A3 -> CareMarketMixed | E3: =S2e_orig!B3 -> 0.073019221 | G3: =B3-E3 -> 0
A4: =S2e!A4 -> demMaleFlag | B4: =S2e!B4 -> 0.15883971 | D4: =S2e_orig!A4 -> Dgn | E4: =S2e_orig!B4 -> 0.15883971 | G4: =B4-E4 -> 0
A5: =S2e!A5 -> healthSelfRatedFair | B5: =S2e!B5 -> -0.21800272 | D5: =S2e_orig!A5 -> Dhe_Fair | E5: =S2e_orig!B5 -> -0.21800272 | G5: =B5-E5 -> 0
A6: =S2e!A6 -> healthSelfRatedGood | B6: =S2e!B6 -> -0.24742633 | D6: =S2e_orig!A6 -> Dhe_Good | E6: =S2e_orig!B6 -> -0.24742633 | G6: =B6-E6 -> 0
A7: =S2e!A7 -> healthSelfRatedVeryGood | B7: =S2e!B7 -> -0.32481386 | D7: =S2e_orig!A7 -> Dhe_VeryGood | E7: =S2e_orig!B7 -> -0.32481386 | G7: =B7-E7 -> 0
A8: =S2e!A8 -> healthSelfRatedExcellent | B8: =S2e!B8 -> -0.54388519 | D8: =S2e_orig!A8 -> Dhe_Excellent | E8: =S2e_orig!B8 -> -0.54388519 | G8: =B8-E8 -> 0
A9: =S2e!A9 -> demPartnerStatusPartnered | B9: =S2e!B9 -> 0.055342145 | D9: =S2e_orig!A9 -> Partnered | E9: =S2e_orig!B9 -> 0.055342145 | G9: =B9-E9 -> 0
A10: =S2e!A10 -> eduHighestC4Medium | B10: =S2e!B10 -> -0.008853895 | D10: =S2e_orig!A10 -> Deh_c4_Medium | E10: =S2e_orig!B10 -> -0.008853895 | G10: =B10-E10 -> 0
A11: =S2e!A11 -> eduHighestC4Low | B11: =S2e!B11 -> 0.12565147 | D11: =S2e_orig!A11 -> Deh_c4_Low | E11: =S2e_orig!B11 -> 0.12565147 | G11: =B11-E11 -> 0
A12: =S2e!A12 -> yHhQuintilesMonthC5Q2 | B12: =S2e!B12 -> -0.078350465 | D12: =S2e_orig!A12 -> HHincomeQ2 | E12: =S2e_orig!B12 -> -0.078350465 | G12: =B12-E12 -> 0
A13: =S2e!A13 -> yHhQuintilesMonthC5Q3 | B13: =S2e!B13 -> -0.19452192 | D13: =S2e_orig!A13 -> HHincomeQ3 | E13: =S2e_orig!B13 -> -0.19452192 | G13: =B13-E13 -> 0
... A32: =S2e!A32 -> Constant | B32: =S2e!B32 -> 2.1594384 | D32: =S2e_orig!A32 -> Constant | E32: =S2e_orig!B32 -> 2.1594384 | G32: =B32-E32 -> 0

Sheet S3a-comp
A1: =S3a!A1 -> REGRESSOR | B1: =S3a!B1 -> COEFFICIENT | D1: =S3a_orig!A1 -> REGRESSOR | E1: =S3a_orig!B1 -> COEFFICIENT | G1: comp
A2: =S3a!A2 -> careProvidedFlagL1 | B2: =S3a!B2 -> 1.7326511 | D2: =S3a_orig!A2 -> ProvideCare_L1 | E2: =S3a_orig!B2 -> 1.7326511 | G2: =B2-E2 -> 0
A3: =S3a!A3 -> careNeedFlag | B3: =S3a!B3 -> -0.19339219 | D3: =S3a_orig!A3 -> NeedCare | E3: =S3a_orig!B3 -> -0.19339219 | G3: =B3-E3 -> 0
A4: =S3a!A4 -> careReceivedFlag | B4: =S3a!B4 -> -0.1543808 | D4: =S3a_orig!A4 -> ReceiveCare | E4: =S3a_orig!B4 -> -0.1543808 | G4: =B4-E4 -> 0
A5: =S3a!A5 -> demMaleFlag | B5: =S3a!B5 -> -0.12125404 | D5: =S3a_orig!A5 -> Dgn | E5: =S3a_orig!B5 -> -0.12125404 | G5: =B5-E5 -> 0
A6: =S3a!A6 -> demAge30to34 | B6: =S3a!B6 -> 0.1869161 | D6: =S3a_orig!A6 -> Age30to34 | E6: =S3a_orig!B6 -> 0.1869161 | G6: =B6-E6 -> 0
A7: =S3a!A7 -> demAge35to39 | B7: =S3a!B7 -> 0.2631549 | D7: =S3a_orig!A7 -> Age35to39 | E7: =S3a_orig!B7 -> 0.2631549 | G7: =B7-E7 -> 0
A8: =S3a!A8 -> demAge40to44 | B8: =S3a!B8 -> 0.29919214 | D8: =S3a_orig!A8 -> Age40to44 | E8: =S3a_orig!B8 -> 0.29919214 | G8: =B8-E8 -> 0
A9: =S3a!A9 -> demAge45to49 | B9: =S3a!B9 -> 0.38929563 | D9: =S3a_orig!A9 -> Age45to49 | E9: =S3a_orig!B9 -> 0.38929563 | G9: =B9-E9 -> 0
A10: =S3a!A10 -> demAge50to54 | B10: =S3a!B10 -> 0.43534554 | D10: =S3a_orig!A10 -> Age50to54 | E10: =S3a_orig!B10 -> 0.43534554 | G10: =B10-E10 -> 0
A11: =S3a!A11 -> demAge55to59 | B11: =S3a!B11 -> 0.39028061 | D11: =S3a_orig!A11 -> Age55to59 | E11: =S3a_orig!B11 -> 0.39028061 | G11: =B11-E11 -> 0
A12: =S3a!A12 -> demAge60to64 | B12: =S3a!B12 -> 0.36278579 | D12: =S3a_orig!A12 -> Age60to64 | E12: =S3a_orig!B12 -> 0.36278579 | G12: =B12-E12 -> 0
A13: =S3a!A13 -> demAge65to69 | B13: =S3a!B13 -> 0.32689542 | D13: =S3a_orig!A13 -> Age65to69 | E13: =S3a_orig!B13 -> 0.32689542 | G13: =B13-E13 -> 0
... A45: =S3a!A45 -> Constant | B45: =S3a!B45 -> -1.9191345 | D45: =S3a_orig!A45 -> Constant | E45: =S3a_orig!B45 -> -1.9191345 | G45: =B45-E45 -> 0

Sheet S3b-comp
A1: =S3b!A1 -> REGRESSOR | B1: =S3b!B1 -> COEFFICIENT | D1: =S3b_orig!A1 -> REGRESSOR | E1: =S3b_orig!B1 -> COEFFICIENT | G1: comp
A2: =S3b!A2 -> careProvidedFlagL1 | B2: =S3b!B2 -> 1.7671684 | D2: =S3b_orig!A2 -> ProvideCare_L1 | E2: =S3b_orig!B2 -> 1.7671684 | G2: =B2-E2 -> 0
A3: =S3b!A3 -> careNeedFlag | B3: =S3b!B3 -> -0.11580122 | D3: =S3b_orig!A3 -> NeedCare | E3: =S3b_orig!B3 -> -0.11580122 | G3: =B3-E3 -> 0
A4: =S3b!A4 -> careReceivedFlag | B4: =S3b!B4 -> -0.18533911 | D4: =S3b_orig!A4 -> ReceiveCare | E4: =S3b_orig!B4 -> -0.18533911 | G4: =B4-E4 -> 0
A5: =S3b!A5 -> demMaleFlag | B5: =S3b!B5 -> -0.15370725 | D5: =S3b_orig!A5 -> Dgn | E5: =S3b_orig!B5 -> -0.15370725 | G5: =B5-E5 -> 0
A6: =S3b!A6 -> careReceivedPartnerFlag | B6: =S3b!B6 -> 0.66425489 | D6: =S3b_orig!A6 -> ReceiveCarePartner | E6: =S3b_orig!B6 -> 0.66425489 | G6: =B6-E6 -> 0
A7: =S3b!A7 -> careMarketFormalPartner | B7: =S3b!B7 -> -0.48483946 | D7: =S3b_orig!A7 -> CareMarketFormalPartner | E7: =S3b_orig!B7 -> -0.48483946 | G7: =B7-E7 -> 0
A8: =S3b!A8 -> careMarketInformalPartner | B8: =S3b!B8 -> -0.16463146 | D8: =S3b_orig!A8 -> CareMarketInformalPartner | E8: =S3b_orig!B8 -> -0.16463146 | G8: =B8-E8 -> 0
A9: =S3b!A9 -> healthSelfRatedPoor | B9: =S3b!B9 -> -0.012612803 | D9: =S3b_orig!A9 -> Dhe_Poor | E9: =S3b_orig!B9 -> -0.012612803 | G9: =B9-E9 -> 0
A10: =S3b!A10 -> healthSelfRatedFair | B10: =S3b!B10 -> 0.048248016 | D10: =S3b_orig!A10 -> Dhe_Fair | E10: =S3b_orig!B10 -> 0.048248016 | G10: =B10-E10 -> 0
A11: =S3b!A11 -> healthSelfRatedGood | B11: =S3b!B11 -> 0.021417376 | D11: =S3b_orig!A11 -> Dhe_Good | E11: =S3b_orig!B11 -> 0.021417376 | G11: =B11-E11 -> 0
A12: =S3b!A12 -> healthSelfRatedVeryGood | B12: =S3b!B12 -> 0.02136601 | D12: =S3b_orig!A12 -> Dhe_VeryGood | E12: =S3b_orig!B12 -> 0.02136601 | G12: =B12-E12 -> 0
A13: =S3b!A13 -> healthPartnerSelfRatedFair | B13: =S3b!B13 -> -0.61092722 | D13: =S3b_orig!A13 -> Dhesp_Fair | E13: =S3b_orig!B13 -> -0.61092722 | G13: =B13-E13 -> 0
... A39: =S3b!A39 -> Constant | B39: =S3b!B39 -> -0.45676356 | D39: =S3b_orig!A39 -> Constant | E39: =S3b_orig!B39 -> -0.45676356 | G39: =B39-E39 -> 0

Sheet S3c-comp
A1: =S3c!A1 -> REGRESSOR | B1: =S3c!B1 -> COEFFICIENT | D1: =S3c_orig!A1 -> REGRESSOR | E1: =S3c_orig!B1 -> COEFFICIENT | G1: comp
A2: =S3c!A2 -> careHrsProvidedWeekIhsL1 | B2: =S3c!B2 -> 0.35394041 | D2: =S3c_orig!A2 -> HrsProvidedInformalIHS_L1 | E2: =S3c_orig!B2 -> 0.35394041 | G2: =B2-E2 -> 0
A3: =S3c!A3 -> demMaleFlag | B3: =S3c!B3 -> -0.13627711 | D3: =S3c_orig!A3 -> Dgn | E3: =S3c_orig!B3 -> -0.13627711 | G3: =B3-E3 -> 0
A4: =S3c!A4 -> demAge20to24 | B4: =S3c!B4 -> 0.071800147 | D4: =S3c_orig!A4 -> Age20to24 | E4: =S3c_orig!B4 -> 0.071800147 | G4: =B4-E4 -> 0
A5: =S3c!A5 -> demAge25to29 | B5: =S3c!B5 -> 0.32517447 | D5: =S3c_orig!A5 -> Age25to29 | E5: =S3c_orig!B5 -> 0.32517447 | G5: =B5-E5 -> 0
A6: =S3c!A6 -> demAge30to34 | B6: =S3c!B6 -> 0.4548636 | D6: =S3c_orig!A6 -> Age30to34 | E6: =S3c_orig!B6 -> 0.4548636 | G6: =B6-E6 -> 0
A7: =S3c!A7 -> demAge35to39 | B7: =S3c!B7 -> 0.28232431 | D7: =S3c_orig!A7 -> Age35to39 | E7: =S3c_orig!B7 -> 0.28232431 | G7: =B7-E7 -> 0
A8: =S3c!A8 -> demAge40to44 | B8: =S3c!B8 -> 0.29651361 | D8: =S3c_orig!A8 -> Age40to44 | E8: =S3c_orig!B8 -> 0.29651361 | G8: =B8-E8 -> 0
A9: =S3c!A9 -> demAge45to49 | B9: =S3c!B9 -> 0.4116622 | D9: =S3c_orig!A9 -> Age45to49 | E9: =S3c_orig!B9 -> 0.4116622 | G9: =B9-E9 -> 0
A10: =S3c!A10 -> demAge50to54 | B10: =S3c!B10 -> 0.19307168 | D10: =S3c_orig!A10 -> Age50to54 | E10: =S3c_orig!B10 -> 0.19307168 | G10: =B10-E10 -> 0
A11: =S3c!A11 -> demAge55to59 | B11: =S3c!B11 -> 0.1569153 | D11: =S3c_orig!A11 -> Age55to59 | E11: =S3c_orig!B11 -> 0.1569153 | G11: =B11-E11 -> 0
A12: =S3c!A12 -> demAge60to64 | B12: =S3c!B12 -> 0.087487403 | D12: =S3c_orig!A12 -> Age60to64 | E12: =S3c_orig!B12 -> 0.087487403 | G12: =B12-E12 -> 0
A13: =S3c!A13 -> demAge65to69 | B13: =S3c!B13 -> 0.03246383 | D13: =S3c_orig!A13 -> Age65to69 | E13: =S3c_orig!B13 -> 0.03246383 | G13: =B13-E13 -> 0
... A45: =S3c!A45 -> Constant | B45: =S3c!B45 -> 2.0918638 | D45: =S3c_orig!A45 -> Constant | E45: =S3c_orig!B45 -> 2.0918638 | G45: =B45-E45 -> 0

Sheet S3d-comp
A1: =S3d!A1 -> REGRESSOR | B1: =S3d!B1 -> COEFFICIENT | D1: =S3d_orig!A1 -> REGRESSOR | E1: =S3d_orig!B1 -> COEFFICIENT | G1: comp
A2: =S3d!A2 -> careHrsProvidedWeekIhsL1 | B2: =S3d!B2 -> 0.31106092 | D2: =S3d_orig!A2 -> HrsProvidedInformalIHS_L1 | E2: =S3d_orig!B2 -> 0.31106092 | G2: =B2-E2 -> 0
A3: =S3d!A3 -> demMaleFlag | B3: =S3d!B3 -> -0.16296205 | D3: =S3d_orig!A3 -> Dgn | E3: =S3d_orig!B3 -> -0.16296205 | G3: =B3-E3 -> 0
A4: =S3d!A4 -> demAge20to24 | B4: =S3d!B4 -> -0.21415897 | D4: =S3d_orig!A4 -> Age20to24 | E4: =S3d_orig!B4 -> -0.21415897 | G4: =B4-E4 -> 0
A5: =S3d!A5 -> demAge25to29 | B5: =S3d!B5 -> -0.051473896 | D5: =S3d_orig!A5 -> Age25to29 | E5: =S3d_orig!B5 -> -0.051473896 | G5: =B5-E5 -> 0
A6: =S3d!A6 -> demAge30to34 | B6: =S3d!B6 -> -0.06633164 | D6: =S3d_orig!A6 -> Age30to34 | E6: =S3d_orig!B6 -> -0.06633164 | G6: =B6-E6 -> 0
A7: =S3d!A7 -> demAge35to39 | B7: =S3d!B7 -> 0.027378891 | D7: =S3d_orig!A7 -> Age35to39 | E7: =S3d_orig!B7 -> 0.027378891 | G7: =B7-E7 -> 0
A8: =S3d!A8 -> demAge40to44 | B8: =S3d!B8 -> -0.23920834 | D8: =S3d_orig!A8 -> Age40to44 | E8: =S3d_orig!B8 -> -0.23920834 | G8: =B8-E8 -> 0
A9: =S3d!A9 -> demAge45to49 | B9: =S3d!B9 -> -0.23777153 | D9: =S3d_orig!A9 -> Age45to49 | E9: =S3d_orig!B9 -> -0.23777153 | G9: =B9-E9 -> 0
A10: =S3d!A10 -> demAge50to54 | B10: =S3d!B10 -> -0.25724304 | D10: =S3d_orig!A10 -> Age50to54 | E10: =S3d_orig!B10 -> -0.25724304 | G10: =B10-E10 -> 0
A11: =S3d!A11 -> demAge55to59 | B11: =S3d!B11 -> -0.32560769 | D11: =S3d_orig!A11 -> Age55to59 | E11: =S3d_orig!B11 -> -0.32560769 | G11: =B11-E11 -> 0
A12: =S3d!A12 -> demAge60to64 | B12: =S3d!B12 -> -0.32625344 | D12: =S3d_orig!A12 -> Age60to64 | E12: =S3d_orig!B12 -> -0.32625344 | G12: =B12-E12 -> 0
A13: =S3d!A13 -> demAge65to69 | B13: =S3d!B13 -> -0.37623104 | D13: =S3d_orig!A13 -> Age65to69 | E13: =S3d_orig!B13 -> -0.37623104 | G13: =B13-E13 -> 0
... A51: =S3d!A51 -> Constant | B51: =S3d!B51 -> 3.492109 | D51: =S3d_orig!A51 -> Constant | E51: =S3d_orig!B51 -> 3.492109 | G51: =B51-E51 -> 0

Sheet Info
A1: Description: | B1: Model parameters for social care module
A2: Authors: | B2: Justin van de Ven, Ashley Burdett, Matteo Richiardi, Daria Popova
A3: Last edit: | B3: 15 April 2026 (DP)
A5: Process: | B5: Description:
A6: S2a | B6: Prob. need care
A7: S2b | B7: Prob. receive care
A8: S2c | B8: Prob. receive Formal/informal care
A9: S2d | B9: Informal care hours received
A10: S2e | B10: Hours of formal care received
A11: S3a | B11: Prob. provide care, Singles
A12: S3b | B12: Prob. provide care, Partnered
A13: S3c | B13: Hours of informal care provided, Singles
... A20: Notes: | B20: Estimation sample: UK_ipop.dta with grossing up weight dwt
B21: Conditions for processes are defined as globals in master.do

Sheet Gof
A1: Goodness of fit
A3: S2a - Need care
A4: Pseudo R-squared | B4: 0.36461738 | E4: Chi^2 | F4: 14785.972
A5: N | B5: 54373 | E5: Log likelihood | F5: -20016369
A7: S2b - Receive care
A8: Pseudo R-squared | B8: 0.50263891 | E8: Chi^2 | F8: 9545.5902
A9: N | B9: 41190 | E9: Log likelihood | F9: -9105217.8
A11: S2c - Formal vs Informal
A12: Pseudo R-squared | B12: 0.44763566 | E12: Chi^2 | F12: 2344.458
A13: N | B13: 8063 | E13: Log likelihood | F13: -3294026.7
A15: S2d - Hours of informal care received
A16: R-squared | B16: 0.21715921
A17: N | B17: 7172
A19: S2e - Hours of formal care received
A20: R-squared | B20: 0.1525355
A21: N | B21: 2494
A23: S3a - Provide care, Singles
A24: Pseudo R-squared | B24: 0.29773881 | E24: Chi^2 | F24: 10178.2
A25: N | B25: 75641 | E25: Log likelihood | F25: -16772009
A27: S3b - Provide care, Partnered
A28: Pseudo R-squared | B28: 0.33023428 | E28: Chi^2 | F28: 20428.599
A29: N | B29: 111092 | E29: Log likelihood | F29: -31790170
A31: S3c - Hours of informal care provided, Singles
A32: R-squared | B32: 0.31561903
A33: N | B33: 11932
A35: S3d - Hours of informal care provided, Partnered
A36: R-squared | B36: 0.32544962
A37: N | B37: 24828

Sheet S2a_orig
A1: REGRESSOR | B1: COEFFICIENT | C1: NeedCare_L1 | D1: Dgn | E1: Age67to68 | F1: Age69to70 | G1: Age71to72 | H1: Age73to74 | I1: Age75to76 | J1: Age77to78 | K1: Age79to80 | L1: Age81to82 | M1: Age83to84 | N1: Age85plus | O1: Dhe_Fair | P1: Dhe_Good | Q1: Dhe_VeryGood | R1: Dhe_Excellent | S1: Partnered | T1: Deh_c4_Medium | U1: Deh_c4_Low | V1: Y2020 | W1: Y2021 | X1: demRgnUKC | Y1: demRgnUKD | Z1: demRgnUKE | AA1: demRgnUKF | AB1: demRgnUKG | AC1: demRgnUKH | AD1: demRgnUKJ | AE1: demRgnUKK | AF1: demRgnUKL | AG1: demRgnUKM | AH1: demRgnUKN | AI1: demEthnC4Asian | AJ1: demEthnC4Black | AK1: demEthnC4Other | AL1: Constant
A2: NeedCare_L1 | B2: 1.6873924 | C2: 0.00027294044 | D2: 1.3097117e-05 | E2: -3.2689148e-05 | F2: -3.3996891e-05 | G2: -5.0014555e-05 | H2: -5.4472952e-05 | I2: -5.9071034e-05 | J2: -6.0738817e-05 | K2: -6.6418008e-05 | L2: -6.6942143e-05 | M2: -7.9230183e-05 | N2: -9.0583724e-05 | O2: 1.9039568e-05 | P2: 3.6549344e-05 | Q2: 4.6943284e-05 | R2: 4.9403005e-05 | S2: -7.3011003e-06 | T2: -7.0827368e-06 | U2: -1.9939996e-05 | V2: -4.8031705e-06 | W2: 1.7104589e-06 | X2: 8.0717975e-06 | Y2: 8.3251736e-07 | Z2: 4.5637547e-07 | AA2: 3.7451334e-06 | AB2: 3.1596911e-06 | AC2: 1.8702347e-05 | AD2: 4.7896369e-06 | AE2: 1.0139376e-05 | AF2: 6.5306897e-06 | AG2: 2.2617978e-06 | AH2: 1.365322e-06 | AI2: -3.0734437e-05 | AJ2: 1.0464404e-05 | AK2: -8.6245348e-06 | AL2: -7.3527871e-05
A3: Dgn | B3: -0.12684304 | C3: 1.3097117e-05 | D3: 0.00025193158 | E3: -1.0869444e-05 | F3: -1.8536349e-05 | G3: -1.3621841e-05 | H3: -1.6101834e-05 | I3: -2.2415272e-05 | J3: -2.2817241e-05 | K3: -2.0987328e-05 | L3: -3.9362069e-05 | M3: -3.1129982e-05 | N3: -4.6311411e-05 | O3: 2.3209508e-05 | P3: 3.2084256e-05 | Q3: 4.3601913e-05 | R3: 3.1105877e-05 | S3: -5.6668529e-05 | T3: 3.1847363e-05 | U3: 4.3486427e-05 | V3: 9.3840104e-06 | W3: -6.2162645e-06 | X3: 1.8574575e-05 | Y3: 4.7713475e-06 | Z3: 1.3138076e-05 | AA3: -1.8652182e-06 | AB3: 3.564722e-06 | AC3: 7.3898155e-06 | AD3: 8.334713e-06 | AE3: 1.6080173e-05 | AF3: 1.0358242e-05 | AG3: 8.7344686e-07 | AH3: 3.8804626e-07 | AI3: -2.1940878e-05 | AJ3: 1.0517737e-05 | AK3: -2.4188494e-05 | AL3: -0.00013337219
A4: Age67to68 | B4: -0.12345389 | C4: -3.2689148e-05 | D4: -1.0869444e-05 | E4: 0.0011289429 | F4: 0.00058861808 | G4: 0.00059137632 | H4: 0.00059324753 | I4: 0.00059482387 | J4: 0.00059592072 | K4: 0.00059792183 | L4: 0.00059972607 | M4: 0.00060189459 | N4: 0.00060634816 | O4: -1.7644862e-06 | P4: -2.28263e-06 | Q4: 6.8258216e-07 | R4: -6.3033258e-06 | S4: 4.2971427e-06 | T4: -2.0594551e-05 | U4: -3.9839438e-05 | V4: -1.5848866e-06 | W4: -4.5960801e-06 | X4: -1.6917012e-05 | Y4: -5.6421799e-06 | Z4: -7.4114112e-06 | AA4: 4.2261461e-06 | AB4: -1.2725422e-05 | AC4: -1.5194057e-05 | AD4: -7.8536849e-06 | AE4: -2.9529019e-06 | AF4: 2.552223e-06 | AG4: -1.3616426e-05 | AH4: 7.2311498e-08 | AI4: 2.7232105e-05 | AJ4: -5.1515883e-05 | AK4: -1.9830226e-05 | AL4: -0.00054619839
A5: Age69to70 | B5: -0.015198448 | C5: -3.3996891e-05 | D5: -1.8536349e-05 | E5: 0.00058861808 | F5: 0.0010757913 | G5: 0.00059401179 | H5: 0.00059399144 | I5: 0.00059550136 | J5: 0.00059648788 | K5: 0.00059808066 | L5: 0.00060015141 | M5: 0.00060315942 | N5: 0.00060860593 | O5: -1.689838e-05 | P5: -9.39809e-06 | Q5: -8.917978e-06 | R5: -2.484918e-05 | S5: 9.7750074e-06 | T5: -1.2721769e-05 | U5: -3.1220245e-05 | V5: 3.4906221e-06 | W5: 4.7883188e-06 | X5: -1.8357323e-05 | Y5: -2.7241967e-05 | Z5: -2.3875314e-05 | AA5: -1.9948942e-05 | AB5: -2.7114232e-05 | AC5: -1.5768282e-05 | AD5: -2.3440437e-05 | AE5: -2.2583676e-05 | AF5: -1.3439487e-05 | AG5: -1.1915808e-05 | AH5: 8.180719e-07 | AI5: 0.00015245021 | AJ5: -2.7808548e-05 | AK5: -6.7311818e-06 | AL5: -0.00053510337
A6: Age71to72 | B6: 0.02309202 | C6: -5.0014555e-05 | D6: -1.3621841e-05 | E6: 0.00059137632 | F6: 0.00059401179 | G6: 0.0010870341 | H6: 0.00060225428 | I6: 0.0006039467 | J6: 0.00060507446 | K6: 0.00060707464 | L6: 0.00060965701 | M6: 0.00061201388 | N6: 0.00061941397 | O6: -1.9487983e-05 | P6: -3.0913613e-05 | Q6: -2.7515975e-06 | R6: -3.0999546e-05 | S6: 2.6865617e-06 | T6: -1.5632976e-05 | U6: -4.888916e-05 | V6: -1.6964289e-05 | W6: 3.8108783e-06 | X6: -3.180783e-05 | Y6: -3.4734157e-05 | Z6: -2.7826718e-05 | AA6: -3.7629796e-05 | AB6: -4.5508692e-05 | AC6: -3.9530939e-05 | AD6: -3.5953548e-05 | AE6: -3.6564533e-05 | AF6: -8.9483244e-06 | AG6: -2.1954347e-05 | AH6: -5.3065926e-06 | AI6: 5.1060621e-05 | AJ6: -5.0474941e-05 | AK6: 0.00035145525 | AL6: -0.00050406504
A7: Age73to74 | B7: 0.054451814 | C7: -5.4472952e-05 | D7: -1.6101834e-05 | E7: 0.00059324753 | F7: 0.00059399144 | G7: 0.00060225428 | H7: 0.0011037669 | I7: 0.0006069269 | J7: 0.00060859724 | K7: 0.00061118226 | L7: 0.00061333808 | M7: 0.0006163482 | N7: 0.00062453033 | O7: -4.7928072e-05 | P7: -4.2133057e-05 | Q7: -3.1190571e-05 | R7: -3.7154234e-05 | S7: 1.7171433e-05 | T7: -2.0924e-05 | U7: -5.4617295e-05 | V7: -2.5152943e-05 | W7: -2.7653894e-05 | X7: -1.4530196e-05 | Y7: -3.3871987e-05 | Z7: -3.2532627e-05 | AA7: -2.840895e-05 | AB7: -5.1833988e-05 | AC7: -3.5962216e-05 | AD7: -3.4955274e-05 | AE7: -2.7485321e-05 | AF7: -2.4980327e-05 | AG7: -2.8489188e-05 | AH7: -1.162377e-06 | AI7: 6.5516841e-05 | AJ7: -5.1411413e-05 | AK7: 2.8948684e-06 | AL7: -0.00048363888
A8: Age75to76 | B8: 0.15215825 | C8: -5.9071034e-05 | D8: -2.2415272e-05 | E8: 0.00059482387 | F8: 0.00059550136 | G8: 0.0006039467 | H8: 0.0006069269 | I8: 0.0011789938 | J8: 0.00061209387 | K8: 0.00061515056 | L8: 0.0006187716 | M8: 0.00062245898 | N8: 0.00063412253 | O8: -4.3876709e-05 | P8: -4.9403357e-05 | Q8: -4.3166941e-05 | R8: -4.9424451e-05 | S8: 2.8910941e-05 | T8: -3.323286e-05 | U8: -6.7015555e-05 | V8: -2.3370898e-05 | W8: -1.6424547e-05 | X8: 2.6913096e-05 | Y8: -8.4230002e-06 | Z8: -6.1661472e-06 | AA8: 8.1724923e-07 | AB8: -1.2496588e-05 | AC8: -5.7251304e-06 | AD8: -6.4480874e-06 | AE8: -5.2218338e-06 | AF8: -2.8539058e-06 | AG8: 7.9550936e-06 | AH8: 1.9128819e-05 | AI8: 8.4287949e-05 | AJ8: -4.1114183e-05 | AK8: 8.8618727e-06 | AL8: -0.00050338362
A9: Age77to78 | B9: 0.19919676 | C9: -6.0738817e-05 | D9: -2.2817241e-05 | E9: 0.00059592072 | F9: 0.00059648788 | G9: 0.00060507446 | H9: 0.00060859724 | I9: 0.00061209387 | J9: 0.0013242307 | K9: 0.00061911189 | L9: 0.00062267473 | M9: 0.00062662449 | N9: 0.00064042426 | O9: -4.6546736e-05 | P9: -6.1667081e-05 | Q9: -3.2139725e-05 | R9: -5.9169967e-05 | S9: 3.4200213e-05 | T9: -3.7390338e-05 | U9: -7.4293719e-05 | V9: -1.632975e-05 | W9: -1.2248891e-05 | X9: -5.0629195e-07 | Y9: -1.1600304e-05 | Z9: -2.8643986e-05 | AA9: -8.4872608e-06 | AB9: -2.1429251e-05 | AC9: -3.1147763e-05 | AD9: -2.0271494e-05 | AE9: -1.9457024e-05 | AF9: -1.6814344e-05 | AG9: -1.5559887e-05 | AH9: 8.1834133e-06 | AI9: 6.3528315e-05 | AJ9: -9.5775788e-05 | AK9: -2.7062473e-05 | AL9: -0.00048649865
A10: Age79to80 | B10: 0.25040279 | C10: -6.6418008e-05 | D10: -2.0987328e-05 | E10: 0.00059792183 | F10: 0.00059808066 | G10: 0.00060707464 | H10: 0.00061118226 | I10: 0.00061515056 | J10: 0.00061911189 | K10: 0.0014723438 | L10: 0.00062800787 | M10: 0.00063248836 | N10: 0.00064755141 | O10: -7.2234381e-05 | P10: -6.8199452e-05 | Q10: -4.6366683e-05 | R10: -5.8851901e-05 | S10: 4.4961294e-05 | T10: -2.9044446e-05 | U10: -7.3351287e-05 | V10: -6.1207441e-06 | W10: -1.2235071e-05 | X10: -2.9147284e-07 | Y10: -1.7784603e-05 | Z10: -1.2050421e-05 | AA10: -2.1575206e-05 | AB10: -2.8605346e-05 | AC10: -4.2532919e-05 | AD10: -1.4334336e-05 | AE10: -2.7621612e-05 | AF10: -1.6291319e-05 | AG10: -2.2754199e-05 | AH10: -8.268069e-06 | AI10: 6.4280623e-05 | AJ10: -8.9574058e-05 | AK10: 2.11539e-05 | AL10: -0.00048472343
A11: Age81to82 | B11: 0.28255827 | C11: -6.6942143e-05 | D11: -3.9362069e-05 | E11: 0.00059972607 | F11: 0.00060015141 | G11: 0.00060965701 | H11: 0.00061333808 | I11: 0.0006187716 | J11: 0.00062267473 | K11: 0.00062800787 | L11: 0.0017917794 | M11: 0.00063729426 | N11: 0.00065151233 | O11: -8.5236044e-05 | P11: -8.442636e-05 | Q11: -6.0493155e-05 | R11: -7.1989478e-05 | S11: 4.603314e-05 | T11: -1.7018467e-05 | U11: -7.8848893e-05 | V11: -9.833882e-06 | W11: 2.0189141e-05 | X11: 5.3955496e-05 | Y11: 6.7343706e-06 | Z11: -1.1894853e-05 | AA11: -4.7253403e-06 | AB11: -1.2055901e-05 | AC11: -4.5534452e-05 | AD11: -1.4649548e-05 | AE11: -3.0961825e-05 | AF11: -1.9537866e-05 | AG11: -2.4883164e-05 | AH11: -1.44661e-05 | AI11: 4.4613964e-05 | AJ11: -8.9673015e-05 | AK11: 2.466909e-05 | AL11: -0.00047905486
A12: Age83to84 | B12: 0.35127761 | C12: -7.9230183e-05 | D12: -3.1129982e-05 | E12: 0.00060189459 | F12: 0.00060315942 | G12: 0.00061201388 | H12: 0.0006163482 | I12: 0.00062245898 | J12: 0.00062662449 | K12: 0.00063248836 | L12: 0.00063729426 | M12: 0.0019707018 | N12: 0.00066182069 | O12: -5.8583281e-05 | P12: -5.6908756e-05 | Q12: -3.4367194e-05 | R12: -2.9311744e-05 | S12: 6.8342323e-05 | T12: -2.6078882e-05 | U12: -7.1394757e-05 | V12: -2.719476e-06 | W12: 2.7660854e-05 | X12: -2.0542729e-05 | Y12: -4.8541505e-05 | Z12: -6.5818107e-05 | AA12: -5.2238969e-05 | AB12: -4.2774681e-05 | AC12: -8.3899888e-05 | AD12: -7.261212e-05 | AE12: -6.4006179e-05 | AF12: -5.9980341e-05 | AG12: -5.0995396e-05 | AH12: -4.2115061e-05 | AI12: 3.3901291e-05 | AJ12: -7.396501e-05 | AK12: -3.8184982e-05 | AL12: -0.00048079185
A13: Age85plus | B13: 0.51368692 | C13: -9.0583724e-05 | D13: -4.6311411e-05 | E13: 0.00060634816 | F13: 0.00060860593 | G13: 0.00061941397 | H13: 0.00062453033 | I13: 0.00063412253 | J13: 0.00064042426 | K13: 0.00064755141 | L13: 0.00065151233 | M13: 0.00066182069 | N13: 0.0013672982 | O13: -7.3733632e-05 | P13: -0.00010700903 | Q13: -7.9967097e-05 | R13: -8.4079506e-05 | S13: 0.00011508822 | T13: -2.54078e-05 | U13: -9.3190344e-05 | V13: 6.9990029e-06 | W13: 1.200674e-05 | X13: -3.9418818e-05 | Y13: 5.5764236e-07 | Z13: -2.2782634e-05 | AA13: 7.1125162e-06 | AB13: -3.0265137e-05 | AC13: -4.0514008e-05 | AD13: -1.5144879e-05 | AE13: -3.4670217e-05 | AF13: -2.1016803e-05 | AG13: -2.4023955e-05 | AH13: -1.3510577e-05 | AI13: 7.6814733e-05 | AJ13: -8.161535e-05 | AK13: -2.8097116e-06 | AL13: -0.0005010095
... A37: Constant | B37: -0.4408915 | C37: -7.3527871e-05 | D37: -0.00013337219 | E37: -0.00054619839 | F37: -0.00053510337 | G37: -0.00050406504 | H37: -0.00048363888 | I37: -0.00050338362 | J37: -0.00048649865 | K37: -0.00048472343 | L37: -0.00047905486 | M37: -0.00048079185 | N37: -0.0005010095 | O37: -0.00097388101 | P37: -0.00098144036 | Q37: -0.00099825857 | R37: -0.0009583982 | S37: -0.00013348851 | T37: -0.00033482638 | U37: -0.00035542111 | V37: -7.5833832e-05 | W37: -9.8534948e-05 | X37: -0.0010607897 | Y37: -0.0010825139 | Z37: -0.00107461 | AA37: -0.0010162128 | AB37: -0.001044322 | AC37: -0.0010505392 | AD37: -0.0010598993 | AE37: -0.0010639822 | AF37: -0.0010800828 | AG37: -0.0010824759 | AH37: -0.0010721694 | AI37: -0.00045464188 | AJ37: -0.00061061325 | AK37: 1.8436909e-05 | AL37: 0.0029260232

Sheet S2b_orig
A1: REGRESSOR | B1: COEFFICIENT | C1: ReceiveCare_L1 | D1: Dgn | E1: Age67to68 | F1: Age69to70 | G1: Age71to72 | H1: Age73to74 | I1: Age75to76 | J1: Age77to78 | K1: Age79to80 | L1: Age81to82 | M1: Age83to84 | N1: Age85plus | O1: Dhe_Fair | P1: Dhe_Good | Q1: Dhe_VeryGood | R1: Dhe_Excellent | S1: Partnered | T1: Deh_c4_Medium | U1: Deh_c4_Low | V1: HHincomeQ2 | W1: HHincomeQ3 | X1: HHincomeQ4 | Y1: HHincomeQ5 | Z1: Y2020 | AA1: Y2021 | AB1: demRgnUKC | AC1: demRgnUKD | AD1: demRgnUKE | AE1: demRgnUKF | AF1: demRgnUKG | AG1: demRgnUKH | AH1: demRgnUKJ | AI1: demRgnUKK | AJ1: demRgnUKL | AK1: demRgnUKM | AL1: demRgnUKN | AM1: demEthnC4Asian | AN1: demEthnC4Black | AO1: demEthnC4Other | AP1: Constant
A2: ReceiveCare_L1 | B2: 2.2181656 | C2: 0.00069643796 | D2: 3.6414725e-05 | E2: -5.0557064e-05 | F2: -7.1078652e-05 | G2: -8.9888081e-05 | H2: -8.866692e-05 | I2: -7.0963846e-05 | J2: -8.7994977e-05 | K2: -7.4330486e-05 | L2: -6.7900071e-05 | M2: -0.00013033221 | N2: -0.00012860235 | O2: 2.2798116e-05 | P2: 3.1872851e-05 | Q2: 7.0577458e-05 | R2: 0.00011542608 | S2: -1.0585398e-05 | T2: 1.2244034e-05 | U2: -1.3781796e-05 | V2: 3.1964071e-05 | W2: 3.134672e-05 | X2: 3.3120415e-05 | Y2: 4.2099025e-05 | Z2: -5.8274121e-05 | AA2: -9.028906e-06 | AB2: 5.7330779e-05 | AC2: 5.6005579e-06 | AD2: -2.4936114e-06 | AE2: 2.4064016e-05 | AF2: 5.8726108e-07 | AG2: 2.4119858e-05 | AH2: 7.7961337e-06 | AI2: -1.4478226e-05 | AJ2: -2.1957721e-05 | AK2: 4.8257749e-07 | AL2: -5.7032621e-05 | AM2: -1.3056339e-05 | AN2: -1.3830816e-05 | AO2: 5.6157079e-05 | AP2: -0.00016670048
A3: Dgn | B3: -0.12752691 | C3: 3.6414725e-05 | D3: 0.00053279697 | E3: -1.7353806e-06 | F3: 3.2019554e-06 | G3: -3.1024427e-05 | H3: -1.9728672e-05 | I3: -4.2845603e-05 | J3: -3.3731384e-05 | K3: -1.8825868e-05 | L3: -5.5920246e-05 | M3: -5.0798121e-05 | N3: -7.865907e-05 | O3: 2.4171246e-05 | P3: 4.6437897e-05 | Q3: 0.00010586575 | R3: 7.3880337e-05 | S3: -0.00012949883 | T3: 5.25892e-05 | U3: 8.1260015e-05 | V3: 4.2442922e-06 | W3: 3.4583295e-06 | X3: 4.5501227e-06 | Y3: -1.0391211e-05 | Z3: 8.3324933e-06 | AA3: -4.3894907e-05 | AB3: 5.4177348e-05 | AC3: 1.3410111e-05 | AD3: 3.2234754e-05 | AE3: -1.6463008e-05 | AF3: 7.3640977e-08 | AG3: 1.749326e-05 | AH3: 4.9649028e-06 | AI3: 2.7892697e-05 | AJ3: 4.9132153e-06 | AK3: 1.1426253e-05 | AL3: -8.1854584e-06 | AM3: 2.10251e-05 | AN3: -1.7144193e-05 | AO3: -2.1189914e-05 | AP3: -0.00025024726
A4: Age67to68 | B4: -0.13212939 | C4: -5.0557064e-05 | D4: -1.7353806e-06 | E4: 0.0024063575 | F4: 0.0011771617 | G4: 0.0011816045 | H4: 0.0011854236 | I4: 0.001182213 | J4: 0.0011913645 | K4: 0.0011895245 | L4: 0.0011915057 | M4: 0.0011925448 | N4: 0.0011875901 | O4: 3.0596272e-05 | P4: 7.6386929e-05 | Q4: 5.6491252e-05 | R4: 0.00010033082 | S4: -2.7016941e-06 | T4: 1.5643493e-05 | U4: -9.0565257e-06 | V4: -2.0828129e-05 | W4: -1.4822105e-05 | X4: 0.00011805634 | Y4: 9.9889877e-05 | Z4: 3.6271202e-06 | AA4: -0.00013148179 | AB4: -7.8872859e-05 | AC4: -6.4209665e-06 | AD4: 1.4205135e-05 | AE4: -4.2141011e-05 | AF4: -0.00011611805 | AG4: -3.6295026e-05 | AH4: 2.6836206e-05 | AI4: -9.4236133e-05 | AJ4: 3.5985286e-05 | AK4: 2.2034121e-05 | AL4: -2.5386396e-05 | AM4: 8.7430815e-05 | AN4: 4.3734546e-06 | AO4: -0.000175709 | AP4: -0.0011810686
A5: Age69to70 | B5: -0.050951389 | C5: -7.1078652e-05 | D5: 3.2019554e-06 | E5: 0.0011771617 | F5: 0.0022542006 | G5: 0.0011951173 | H5: 0.0011965586 | I5: 0.0011937921 | J5: 0.0012054334 | K5: 0.0012103708 | L5: 0.0012187998 | M5: 0.0012301281 | N5: 0.0012320128 | O5: 2.1778089e-05 | P5: 5.7042398e-05 | Q5: 7.6284889e-05 | R5: 7.9823601e-05 | S5: 4.6622977e-05 | T5: 5.3941174e-06 | U5: -3.9481217e-05 | V5: -4.3744814e-05 | W5: -1.4964014e-05 | X5: 8.7471546e-05 | Y5: 0.00017014681 | Z5: 4.1948182e-05 | AA5: -5.1344357e-05 | AB5: -8.5450379e-05 | AC5: -6.6469943e-05 | AD5: -6.0753064e-05 | AE5: -6.6116736e-05 | AF5: -9.6191031e-05 | AG5: -7.5674049e-05 | AH5: -5.2510779e-05 | AI5: -8.250482e-05 | AJ5: -2.07832e-05 | AK5: -2.5827031e-05 | AL5: -3.8432056e-05 | AM5: 0.00010058777 | AN5: 2.3724194e-05 | AO5: -8.8391748e-05 | AP5: -0.0011729306
A6: Age71to72 | B6: -0.032245555 | C6: -8.9888081e-05 | D6: -3.1024427e-05 | E6: 0.0011816045 | F6: 0.0011951173 | G6: 0.0022893437 | H6: 0.0012022553 | I6: 0.0011997015 | J6: 0.001211994 | K6: 0.0012167587 | L6: 0.0012228188 | M6: 0.0012137437 | N6: 0.0012138146 | O6: 4.1603868e-05 | P6: 7.9813804e-05 | Q6: 7.4508538e-05 | R6: 0.00023987495 | S6: 1.6877444e-05 | T6: 3.8998457e-05 | U6: 3.1306076e-06 | V6: -8.7743722e-05 | W6: -5.8221219e-05 | X6: 7.613536e-05 | Y6: 0.0001788469 | Z6: 1.9244914e-05 | AA6: -0.00010872782 | AB6: -6.4351857e-05 | AC6: -7.8736016e-05 | AD6: -4.3251648e-05 | AE6: -8.8960141e-05 | AF6: -0.00014594423 | AG6: -4.0679977e-05 | AH6: -1.6604031e-05 | AI6: -0.00012262356 | AJ6: -3.7345277e-05 | AK6: -6.9760213e-05 | AL6: -4.2188938e-05 | AM6: 4.3996151e-05 | AN6: 1.7400514e-05 | AO6: -8.5991344e-05 | AP6: -0.0011382895
A7: Age73to74 | B7: -0.021038734 | C7: -8.866692e-05 | D7: -1.9728672e-05 | E7: 0.0011854236 | F7: 0.0011965586 | G7: 0.0012022553 | H7: 0.0023648499 | I7: 0.0012095299 | J7: 0.0012247743 | K7: 0.0012326156 | L7: 0.0012383894 | M7: 0.0012248058 | N7: 0.0012402687 | O7: -3.0266544e-05 | P7: 4.0302364e-05 | Q7: 3.8430951e-05 | R7: 0.00010961196 | S7: 5.2786523e-05 | T7: 1.1796172e-05 | U7: -5.9547113e-05 | V7: -7.84015e-05 | W7: -4.2108941e-05 | X7: 9.6857305e-05 | Y7: 9.6517788e-05 | Z7: -7.8072786e-05 | AA7: -0.00014729272 | AB7: 3.3282276e-05 | AC7: -7.3500475e-05 | AD7: -1.8692218e-05 | AE7: -4.2320067e-05 | AF7: -0.00014911457 | AG7: -4.4248172e-05 | AH7: 5.8151446e-06 | AI7: -5.8545917e-05 | AJ7: -2.0894357e-05 | AK7: -1.8714854e-05 | AL7: -5.1774114e-07 | AM7: 0.0001596067 | AN7: 4.1655637e-05 | AO7: -0.00019699016 | AP7: -0.0011073635
A8: Age75to76 | B8: 0.11811801 | C8: -7.0963846e-05 | D8: -4.2845603e-05 | E8: 0.001182213 | F8: 0.0011937921 | G8: 0.0011997015 | H8: 0.0012095299 | I8: 0.0024521605 | J8: 0.0012264256 | K8: 0.0012349709 | L8: 0.0012458851 | M8: 0.0012357762 | N8: 0.0012582188 | O8: -4.0267264e-05 | P8: -1.3914254e-05 | Q8: -2.2701766e-05 | R8: -1.0911539e-05 | S8: 8.8053998e-05 | T8: -2.0478409e-06 | U8: -7.7694916e-05 | V8: -9.4275753e-05 | W8: -3.919901e-05 | X8: 8.2845619e-05 | Y8: 7.2067934e-05 | Z8: -3.8637855e-05 | AA8: -0.0001217753 | AB8: 6.0709173e-05 | AC8: 3.9298475e-05 | AD8: 5.025477e-05 | AE8: 3.6109478e-05 | AF8: -5.462951e-05 | AG8: 4.0278155e-06 | AH8: 6.9370364e-05 | AI8: -2.1726922e-05 | AJ8: 3.1569562e-05 | AK8: 9.0801118e-05 | AL8: 3.9567476e-05 | AM8: 0.00011352607 | AN8: 1.7811561e-05 | AO8: -0.00010505703 | AP8: -0.001139466
A9: Age77to78 | B9: 0.17611269 | C9: -8.7994977e-05 | D9: -3.3731384e-05 | E9: 0.0011913645 | F9: 0.0012054334 | G9: 0.001211994 | H9: 0.0012247743 | I9: 0.0012264256 | J9: 0.0026446761 | K9: 0.0012489799 | L9: 0.001253275 | M9: 0.0012424773 | N9: 0.0012603938 | O9: -1.2978493e-05 | P9: -1.9295115e-05 | Q9: 4.022627e-05 | R9: 5.7639739e-05 | S9: 4.7956595e-05 | T9: 3.8506524e-05 | U9: -4.8237521e-05 | V9: -0.00010736659 | W9: -3.0047392e-05 | X9: 0.00012206653 | Y9: 0.00012922138 | Z9: -4.9323078e-05 | AA9: -0.00015512822 | AB9: -3.8952883e-05 | AC9: -1.6778608e-05 | AD9: -9.2416618e-05 | AE9: -4.4870708e-05 | AF9: -0.00015220477 | AG9: -4.8447999e-05 | AH9: -4.7489012e-05 | AI9: -0.0001216851 | AJ9: -6.2103723e-05 | AK9: -3.7082998e-05 | AL9: -3.3377018e-05 | AM9: 6.1770585e-05 | AN9: -0.00010464023 | AO9: -0.0002166079 | AP9: -0.0010757258
A10: Age79to80 | B10: 0.23294455 | C10: -7.4330486e-05 | D10: -1.8825868e-05 | E10: 0.0011895245 | F10: 0.0012103708 | G10: 0.0012167587 | H10: 0.0012326156 | I10: 0.0012349709 | J10: 0.0012489799 | K10: 0.0029085969 | L10: 0.0012747278 | M10: 0.0012650508 | N10: 0.0012899298 | O10: -5.8887196e-05 | P10: -3.7187759e-05 | Q10: -2.0992029e-05 | R10: 7.837296e-05 | S10: 0.00011262567 | T10: -5.7457338e-06 | U10: -0.00010689447 | V10: -0.0001575724 | W10: -6.5720501e-05 | X10: 7.2479117e-05 | Y10: 8.4902963e-05 | Z10: -4.2964645e-05 | AA10: -0.00013224594 | AB10: 4.5069295e-05 | AC10: -6.9039783e-05 | AD10: -3.1288312e-05 | AE10: -3.2359389e-05 | AF10: -0.00013229502 | AG10: -5.8420182e-05 | AH10: 4.85535e-06 | AI10: -0.00011882501 | AJ10: -5.031492e-05 | AK10: -3.4897767e-05 | AL10: -5.2370831e-05 | AM10: 8.8746106e-06 | AN10: -8.5303432e-05 | AO10: -0.00019065055 | AP10: -0.0010420752
A11: Age81to82 | B11: 0.30934154 | C11: -6.7900071e-05 | D11: -5.5920246e-05 | E11: 0.0011915057 | F11: 0.0012187998 | G11: 0.0012228188 | H11: 0.0012383894 | I11: 0.0012458851 | J11: 0.001253275 | K11: 0.0012747278 | L11: 0.0034432209 | M11: 0.0012848487 | N11: 0.0013084367 | O11: -0.00015347596 | P11: -0.00013145693 | Q11: -5.41781e-05 | R11: 0.00017003208 | S11: 0.00011813535 | T11: 4.6426235e-05 | U11: -9.1163707e-05 | V11: -6.2788663e-05 | W11: -1.3800966e-05 | X11: 0.0001697731 | Y11: 0.00016750787 | Z11: -5.9454827e-05 | AA11: -4.6913643e-05 | AB11: 0.00011718866 | AC11: -0.00010411506 | AD11: -0.00012563563 | AE11: -8.4629985e-05 | AF11: -0.00022026006 | AG11: -0.00011589637 | AH11: -0.00011249651 | AI11: -0.00018489775 | AJ11: -9.7498029e-05 | AK11: -8.5500201e-05 | AL11: -0.00010250553 | AM11: 2.5258964e-05 | AN11: -5.9159915e-05 | AO11: -0.0001851419 | AP11: -0.0010184515
A12: Age83to84 | B12: 0.36060264 | C12: -0.00013033221 | D12: -5.0798121e-05 | E12: 0.0011925448 | F12: 0.0012301281 | G12: 0.0012137437 | H12: 0.0012248058 | I12: 0.0012357762 | J12: 0.0012424773 | K12: 0.0012650508 | L12: 0.0012848487 | M12: 0.0041022046 | N12: 0.0012887969 | O12: -4.7720865e-05 | P12: 2.2018142e-05 | Q12: 1.4428199e-05 | R12: 9.8651237e-05 | S12: 0.00013796594 | T12: 2.6260352e-05 | U12: -4.7996171e-05 | V12: -0.00013938148 | W12: -0.00010055349 | X12: 5.0816606e-05 | Y12: 3.9792835e-05 | Z12: 3.2898684e-05 | AA12: 5.302448e-05 | AB12: 0.00012146721 | AC12: -8.3826723e-06 | AD12: -7.6962659e-05 | AE12: -5.7484106e-05 | AF12: -3.1499848e-05 | AG12: -0.0001159597 | AH12: -5.2729442e-05 | AI12: -6.1242627e-05 | AJ12: -6.9185164e-05 | AK12: -2.0749368e-05 | AL12: -6.5570242e-05 | AM12: 2.7061142e-05 | AN12: -3.3598159e-05 | AO12: -0.00019711667 | AP12: -0.0011417784
A13: Age85plus | B13: 0.53110232 | C13: -0.00012860235 | D13: -7.865907e-05 | E13: 0.0011875901 | F13: 0.0012320128 | G13: 0.0012138146 | H13: 0.0012402687 | I13: 0.0012582188 | J13: 0.0012603938 | K13: 0.0012899298 | L13: 0.0013084367 | M13: 0.0012887969 | N13: 0.0024749653 | O13: -9.7574555e-05 | P13: -0.0001132346 | Q13: -6.8374972e-05 | R13: -9.5900471e-05 | S13: 0.00025114024 | T13: -1.0366317e-05 | U13: -0.00013149912 | V13: -8.5396822e-05 | W13: -4.1091962e-05 | X13: 7.9297111e-05 | Y13: 9.7670791e-05 | Z13: -1.606425e-05 | AA13: -7.2475971e-05 | AB13: -0.00011268795 | AC13: -6.4814821e-05 | AD13: -0.00010419148 | AE13: -2.1243469e-05 | AF13: -0.00019337826 | AG13: -8.4158048e-05 | AH13: -2.3779323e-05 | AI13: -0.0001671789 | AJ13: -6.279662e-05 | AK13: -5.6072583e-05 | AL13: -7.9302639e-05 | AM13: 8.1720764e-05 | AN13: -7.2758776e-05 | AO13: -0.00020963635 | AP13: -0.001062764
... A41: Constant | B41: -0.83951647 | C41: -0.00016670048 | D41: -0.00025024726 | E41: -0.0011810686 | F41: -0.0011729306 | G41: -0.0011382895 | H41: -0.0011073635 | I41: -0.001139466 | J41: -0.0010757258 | K41: -0.0010420752 | L41: -0.0010184515 | M41: -0.0011417784 | N41: -0.001062764 | O41: -0.0014069079 | P41: -0.0013690446 | Q41: -0.0013997813 | R41: -0.0013231035 | S41: -0.00013263713 | T41: -0.00099984664 | U41: -0.0011560534 | V41: -0.00060911236 | W41: -0.00075985563 | X41: -0.0011645045 | Y41: -0.0012310058 | Z41: -0.00020197751 | AA41: -0.00012503987 | AB41: -0.0025033826 | AC41: -0.0024668318 | AD41: -0.0024704705 | AE41: -0.0023210078 | AF41: -0.0023712612 | AG41: -0.0024261153 | AH41: -0.0024391376 | AI41: -0.0023996934 | AJ41: -0.0024441011 | AK41: -0.0025253855 | AL41: -0.0024811321 | AM41: -0.0014398125 | AN41: -0.0015561798 | AO41: -0.00052127625 | AP41: 0.006555914

Sheet S2c_orig_raw
A1: CATEGORY | B1: REGRESSOR | C1: COEFFICIENT
A2: Informal | B2: o.CareMarketFormal_L1 | C2: 0
A3: Informal | B3: o.CareMarketInformal_L1 | C3: 0
A4: Informal | B4: o.CareMarketMixed_L1 | C4: 0
A5: Informal | B5: o.Dgn | C5: 0
A6: Informal | B6: o.Age67to68 | C6: 0
A7: Informal | B7: o.Age69to70 | C7: 0
A8: Informal | B8: o.Age71to72 | C8: 0
A9: Informal | B9: o.Age73to74 | C9: 0
A10: Informal | B10: o.Age75to76 | C10: 0
A11: Informal | B11: o.Age77to78 | C11: 0
A12: Informal | B12: o.Age79to80 | C12: 0
A13: Informal | B13: o.Age81to82 | C13: 0
... A127: Formal | B127: _cons | C127: -0.96075646

Sheet S2c_orig
A1: REGRESSOR | B1: COEFFICIENT | C1: CareMarketFormal_L1_Mixed | D1: CareMarketInformal_L1_Mixed | E1: CareMarketMixed_L1_Mixed | F1: Dgn_Mixed | G1: Age67to68_Mixed | H1: Age69to70_Mixed | I1: Age71to72_Mixed | J1: Age73to74_Mixed | K1: Age75to76_Mixed | L1: Age77to78_Mixed | M1: Age79to80_Mixed | N1: Age81to82_Mixed | O1: Age83to84_Mixed | P1: Age85plus_Mixed | Q1: Dhe_Fair_Mixed | R1: Dhe_Good_Mixed | S1: Dhe_VeryGood_Mixed | T1: Dhe_Excellent_Mixed | U1: Partnered_Mixed | V1: Deh_c4_Medium_Mixed | W1: Deh_c4_Low_Mixed | X1: HHincomeQ2_Mixed | Y1: HHincomeQ3_Mixed | Z1: HHincomeQ4_Mixed | AA1: HHincomeQ5_Mixed | AB1: Y2020_Mixed | AC1: Y2021_Mixed | AD1: demRgnUKC_Mixed | AE1: demRgnUKD_Mixed | AF1: demRgnUKE_Mixed | AG1: demRgnUKF_Mixed | AH1: demRgnUKG_Mixed | AI1: demRgnUKH_Mixed | AJ1: demRgnUKJ_Mixed | AK1: demRgnUKK_Mixed | AL1: demRgnUKL_Mixed | AM1: demRgnUKM_Mixed | AN1: demRgnUKN_Mixed | AO1: demEthnC4Asian_Mixed | AP1: demEthnC4Black_Mixed | AQ1: demEthnC4Other_Mixed | AR1: Constant_Mixed | AS1: CareMarketFormal_L1_Formal | AT1: CareMarketInformal_L1_Formal | AU1: CareMarketMixed_L1_Formal | AV1: Dgn_Formal | AW1: Age67to68_Formal | AX1: Age69to70_Formal | AY1: Age71to72_Formal | AZ1: Age73to74_Formal | BA1: Age75to76_Formal | BB1: Age77to78_Formal | BC1: Age79to80_Formal | BD1: Age81to82_Formal | BE1: Age83to84_Formal | BF1: Age85plus_Formal | BG1: Dhe_Fair_Formal | BH1: Dhe_Good_Formal | BI1: Dhe_VeryGood_Formal | BJ1: Dhe_Excellent_Formal | BK1: Partnered_Formal | BL1: Deh_c4_Medium_Formal | BM1: Deh_c4_Low_Formal | BN1: HHincomeQ2_Formal | BO1: HHincomeQ3_Formal | BP1: HHincomeQ4_Formal | BQ1: HHincomeQ5_Formal | BR1: Y2020_Formal | BS1: Y2021_Formal | BT1: demRgnUKC_Formal | BU1: demRgnUKD_Formal | BV1: demRgnUKE_Formal | BW1: demRgnUKF_Formal | BX1: demRgnUKG_Formal | BY1: demRgnUKH_Formal | BZ1: demRgnUKJ_Formal | CA1: demRgnUKK_Formal | CB1: demRgnUKL_Formal | CC1: demRgnUKM_Formal | CD1: demRgnUKN_Formal | CE1: demEthnC4Asian_Formal | CF1: demEthnC4Black_Formal | CG1: demEthnC4Other_Formal | CH1: Constant_Formal
A2: CareMarketFormal_L1_Mixed | B2: 1.2882068 | C2: 0.043231651 | D2: 0.0053946808 | E2: 0.0051403454 | F2: 0.00010427315 | G2: -0.00021993938 | H2: -0.0018645217 | I2: -0.0020541403 | J2: -0.0003571186 | K2: -0.0035552266 | L2: -0.0024896578 | M2: -0.0024045829 | N2: -0.00095026769 | O2: -0.0026139553 | P2: -0.0035880704 | Q2: 0.001453968 | R2: 0.0019349739 | S2: 0.0014992083 | T2: 0.0025876088 | U2: 0.00073994369 | V2: 0.0006418005 | W2: 0.00042500064 | X2: 0.00051806998 | Y2: 0.00084151354 | Z2: 0.0017054435 | AA2: 0.00020000076 | AB2: -0.0016449181 | AC2: -0.00021058282 | AD2: 0.0010574802 | AE2: 0.0023723218 | AF2: 0.0016098264 | AG2: 0.0022077637 | AH2: 0.0015310031 | AI2: 0.0016945269 | AJ2: 0.0016137497 | AK2: 0.0015657441 | AL2: 0.0020226957 | AM2: 0.0013709984 | AN2: 0.00090770463 | AO2: 0.0014056279 | AP2: -0.0033556475 | AQ2: 0.0023879061 | AR2: -0.0069328854 | AS2: 0.021465901 | AT2: 0.00052317339 | AU2: 0.00037939555 | AV2: 0.00059432744 | AW2: -0.0018448064 | AX2: -0.00042582076 | AY2: -0.0023864564 | AZ2: -0.003046529 | BA2: -0.0016535512 | BB2: -0.00093350681 | BC2: -4.4266453e-05 | BD2: -0.004774274 | BE2: -0.0019889818 | BF2: -0.00027233753 | BG2: -0.00018688149 | BH2: 0.0016152351 | BI2: -0.00053911915 | BJ2: 0.011864548 | BK2: -0.00057142173 | BL2: -6.9612235e-05 | BM2: -0.00038969782 | BN2: 0.00015501277 | BO2: -0.003030438 | BP2: -0.0019202241 | BQ2: -0.00074889691 | BR2: -0.0011396846 | BS2: -0.0020130172 | BT2: -0.0077019078 | BU2: -0.0021143847 | BV2: -0.00056358862 | BW2: -0.0038936765 | BX2: -0.004445775 | BY2: -0.00031922516 | BZ2: -0.0041977246 | CA2: -0.00030062379 | CB2: -0.0041504731 | CC2: -0.0021974254 | CD2: -0.0030162663 | CE2: -0.00013836613 | CF2: -0.0066251896 | CG2: 0.00024101339 | CH2: 0.0036224691
A3: CareMarketInformal_L1_Mixed | B3: -1.2997993 | C3: 0.0053946808 | D3: 0.011769462 | E3: 0.0051919759 | F3: 0.00012571691 | G3: 0.00063055265 | H3: -3.6411195e-05 | I3: 4.1643355e-05 | J3: -0.0013433683 | K3: -0.0016368725 | L3: -0.0019474116 | M3: -0.0019819147 | N3: -0.0028534232 | O3: -0.0017984792 | P3: -0.0028100185 | Q3: 0.00093425222 | R3: 0.0016476112 | S3: 0.0014712549 | T3: 0.00047943216 | U3: 0.00021969575 | V3: -0.00074119351 | W3: -0.0017373093 | X3: 0.0014234817 | Y3: 0.0013460187 | Z3: 1.4061097e-05 | AA3: -0.00067292735 | AB3: -0.0015414414 | AC3: 0.0005477043 | AD3: 0.0014636627 | AE3: 0.0011244881 | AF3: 0.0012416416 | AG3: -0.00058218168 | AH3: -2.4072646e-05 | AI3: 0.00017979607 | AJ3: 0.00026547321 | AK3: 0.00075178446 | AL3: -7.6448492e-05 | AM3: -0.00058107078 | AN3: -0.00048821206 | AO3: 2.7970184e-05 | AP3: -0.00021452073 | AQ3: 0.0010761589 | AR3: -0.0045615769 | AS3: 0.001171542 | AT3: 0.0019420227 | AU3: 0.0010504827 | AV3: 6.3305679e-05 | AW3: -0.00010331295 | AX3: -5.338899e-05 | AY3: -9.2689422e-05 | AZ3: -0.0007199232 | BA3: -0.00050100624 | BB3: -0.00043949782 | BC3: -0.00057957499 | BD3: -0.00096636245 | BE3: -0.00047572166 | BF3: -0.00093393989 | BG3: 0.00031468225 | BH3: 0.0004999897 | BI3: 0.00051327394 | BJ3: 0.0010408047 | BK3: 0.00036482566 | BL3: -0.0003006164 | BM3: -0.00049260828 | BN3: 0.00010612306 | BO3: 0.00016083157 | BP3: -0.00073287386 | BQ3: -0.00038808488 | BR3: -0.00042509218 | BS3: 0.00030063208 | BT3: 0.00054598636 | BU3: 0.00053208915 | BV3: 0.00021445507 | BW3: -0.00017833734 | BX3: 5.8846246e-05 | BY3: -9.3942801e-05 | BZ3: 0.00021651105 | CA3: 0.0002118517 | CB3: -0.00017026689 | CC3: -0.0001875041 | CD3: -0.00049871707 | CE3: -0.00013826944 | CF3: 8.3689089e-05 | CG3: -0.00015953872 | CH3: -0.00077221851
A4: CareMarketMixed_L1_Mixed | B4: 3.0061834 | C4: 0.0051403454 | D4: 0.0051919759 | E4: 0.01547645 | F4: -0.00014900964 | G4: -0.0017970738 | H4: -0.00088776287 | I4: -0.0018034936 | J4: -0.0010785289 | K4: -0.001394385 | L4: -0.0021409994 | M4: -0.0017559541 | N4: -0.0010946813 | O4: -0.00057899077 | P4: -0.0021315359 | Q4: 0.000814685 | R4: 0.00054065387 | S4: 0.00057484221 | T4: -0.0017057096 | U4: -0.00018584789 | V4: -0.00093819152 | W4: -0.0017297059 | X4: 0.0014678087 | Y4: 0.0015131069 | Z4: 0.0011730188 | AA4: -6.0645062e-05 | AB4: -0.0020610891 | AC4: 7.6747208e-05 | AD4: 0.0002977066 | AE4: -0.00019926923 | AF4: 2.74466e-07 | AG4: -0.00043720824 | AH4: 4.3497965e-05 | AI4: 0.00029796244 | AJ4: 0.00060342418 | AK4: -0.00063926163 | AL4: -0.00045710957 | AM4: -0.0010040912 | AN4: -0.0013541068 | AO4: -0.00051054623 | AP4: 0.001028415 | AQ4: -0.00025564256 | AR4: -0.0033560856 | AS4: 0.0010349208 | AT4: 0.0010956861 | AU4: 0.0097246261 | AV4: -0.00011416836 | AW4: -0.00077325021 | AX4: -0.00044463986 | AY4: -0.00070797568 | AZ4: -0.0004170918 | BA4: -0.00037792563 | BB4: -0.00058625133 | BC4: -0.00068544329 | BD4: -0.00013171926 | BE4: 0.00016390928 | BF4: -0.00062050405 | BG4: 0.00045921821 | BH4: 0.00021593217 | BI4: 0.00016515276 | BJ4: 0.00030346032 | BK4: 0.00012804303 | BL4: -0.00034993321 | BM4: -0.00058582344 | BN4: 0.00022013466 | BO4: 0.00036839079 | BP4: -0.00011845628 | BQ4: -0.00012035023 | BR4: -0.00077160092 | BS4: 0.0001988442 | BT4: -0.00038443349 | BU4: -0.00035950367 | BV4: -0.00056330217 | BW4: -0.00050746433 | BX4: -6.5099816e-05 | BY4: -0.00032337634 | BZ4: 0.00011355886 | CA4: -0.00066435562 | CB4: -0.00061455388 | CC4: -0.00063840801 | CD4: -0.00099018669 | CE4: -0.0005566352 | CF4: 0.00068841947 | CG4: -0.00076467438 | CH4: -0.00013070251
A5: Dgn_Mixed | B5: -0.1764564 | C5: 0.00010427315 | D5: 0.00012571691 | E5: -0.00014900964 | F5: 0.0087254067 | G5: -0.00050997048 | H5: 8.6087656e-05 | I5: 0.00029294222 | J5: 0.00038709125 | K5: -2.7116922e-05 | L5: -0.00027907104 | M5: -0.00088343861 | N5: -0.0018564324 | O5: -0.00067251423 | P5: -0.00076550452 | Q5: 0.00093757444 | R5: 0.0010339667 | S5: 0.0013203745 | T5: -0.00059622366 | U5: -0.0017199465 | V5: 0.00071741363 | W5: 0.0013903275 | X5: 0.0002645993 | Y5: 0.00017899795 | Z5: 0.00012356533 | AA5: 0.00014946934 | AB5: -0.0003541701 | AC5: -0.0001154798 | AD5: 0.00078736817 | AE5: 0.0010556337 | AF5: 0.00041705667 | AG5: 0.00029127545 | AH5: 0.001176881 | AI5: 0.00032478686 | AJ5: -0.00020328693 | AK5: 0.00065175212 | AL5: 0.00064451677 | AM5: 0.00017347089 | AN5: 0.00018845413 | AO5: -1.8073199e-05 | AP5: 2.0800991e-05 | AQ5: 0.001990577 | AR5: -0.0043467786 | AS5: 2.8350964e-05 | AT5: 0.00028036298 | AU5: -0.00058302663 | AV5: 0.0029144575 | AW5: -0.001067191 | AX5: -0.0007336335 | AY5: -0.00014145808 | AZ5: -0.00022507422 | BA5: -0.00015704098 | BB5: -0.00077245476 | BC5: -0.00025449599 | BD5: -0.0012155185 | BE5: -0.00033684275 | BF5: -0.00029427611 | BG5: 0.00030601257 | BH5: -0.00017408998 | BI5: 5.6606835e-05 | BJ5: 9.0703032e-05 | BK5: -0.00033728273 | BL5: -0.00011309886 | BM5: 0.00021401518 | BN5: -0.00011260717 | BO5: -0.00025976831 | BP5: -0.00034570048 | BQ5: -0.00022071085 | BR5: 0.00021661644 | BS5: 0.00031682982 | BT5: 0.00057904351 | BU5: 0.00070292111 | BV5: -0.00036207248 | BW5: -4.263255e-05 | BX5: 0.00033677156 | BY5: 0.00048349514 | BZ5: 0.00037120944 | CA5: 0.00035227734 | CB5: 0.00046003172 | CC5: 0.00017271622 | CD5: 0.00044917131 | CE5: -0.00023999389 | CF5: 0.00036976857 | CG5: 0.00089534613 | CH5: -0.00089352528
A6: Age67to68_Mixed | B6: -0.33236079 | C6: -0.00021993938 | D6: 0.00063055265 | E6: -0.0017970738 | F6: -0.00050997048 | G6: 0.063875119 | H6: 0.03146254 | I6: 0.031956518 | J6: 0.031491279 | K6: 0.031801773 | L6: 0.031941302 | M6: 0.032014993 | N6: 0.032295201 | O6: 0.032252606 | P6: 0.032850285 | Q6: -0.00094314074 | R6: -0.0010649452 | S6: -0.0015308762 | T6: -0.00015512247 | U6: 0.002349615 | V6: 0.00030946681 | W6: -0.00057992045 | X6: -5.2375726e-05 | Y6: 0.00057008125 | Z6: 0.00046164584 | AA6: 0.00049969226 | AB6: 0.00057247123 | AC6: 0.00062719164 | AD6: 0.0043587135 | AE6: 0.0017192212 | AF6: 0.0035380887 | AG6: 0.0020207352 | AH6: 3.6671473e-05 | AI6: 0.00032306665 | AJ6: -0.0002338703 | AK6: 0.00086347745 | AL6: 0.0024810695 | AM6: 0.0033002776 | AN6: 0.0017890171 | AO6: 0.0022393505 | AP6: 0.0046339811 | AQ6: 0.004715338 | AR6: -0.033737726 | AS6: -0.00063733686 | AT6: -0.00078363468 | AU6: -0.0020738551 | AV6: -0.00095622472 | AW6: 0.014665951 | AX6: 0.0069134484 | AY6: 0.0070640828 | AZ6: 0.0068055553 | BA6: 0.0069962182 | BB6: 0.0069726658 | BC6: 0.0068820227 | BD6: 0.0070599723 | BE6: 0.0070985926 | BF6: 0.0075816282 | BG6: -0.0010404353 | BH6: -0.0011580128 | BI6: -0.00062528799 | BJ6: -0.00095849712 | BK6: 0.0013901837 | BL6: 0.00063233962 | BM6: -3.7952322e-05 | BN6: -0.00025700484 | BO6: -0.00015593087 | BP6: -0.0011828958 | BQ6: -0.00018119945 | BR6: 0.0012508061 | BS6: 0.00026249165 | BT6: 0.0031591546 | BU6: 0.0014020092 | BV6: 0.0022186112 | BW6: 0.0023930581 | BX6: 0.00062115831 | BY6: 0.0026888769 | BZ6: 0.00039728959 | CA6: 0.0017857223 | CB6: 0.0020541974 | CC6: 0.0019664701 | CD6: 0.0018683468 | CE6: 0.0014090692 | CF6: 0.0022382119 | CG6: -0.00012861278 | CH6: -0.0080165179
A7: Age69to70_Mixed | B7: 0.11943924 | C7: -0.0018645217 | D7: -3.6411195e-05 | E7: -0.00088776287 | F7: 8.6087656e-05 | G7: 0.03146254 | H7: 0.061776392 | I7: 0.032901786 | J7: 0.032310423 | K7: 0.033125777 | L7: 0.03312133 | M7: 0.032872902 | N7: 0.034107422 | O7: 0.034154846 | P7: 0.03451415 | Q7: -0.0038448348 | R7: -0.0045489103 | S7: -0.0044550916 | T7: -0.0038838357 | U7: 0.0014219297 | V7: -0.00753587 | W7: -0.0071509149 | X7: -1.7694585e-05 | Y7: -0.00093716158 | Z7: 0.0007519938 | AA7: -0.0010274049 | AB7: -0.00030190602 | AC7: 0.0060759381 | AD7: 0.0072504468 | AE7: 0.0052146525 | AF7: 0.0039703022 | AG7: 0.0015684109 | AH7: 0.0020422151 | AI7: 0.0010143389 | AJ7: -0.00044804932 | AK7: 0.00039132909 | AL7: 0.0029694989 | AM7: 0.0027842807 | AN7: 0.0030962623 | AO7: 0.00026201979 | AP7: 0.005526845 | AQ7: 0.0054772714 | AR7: -0.027177449 | AS7: -0.00067389225 | AT7: -0.00041470838 | AU7: -0.0013064404 | AV7: -0.00056049019 | AW7: 0.0071436512 | AX7: 0.015389521 | AY7: 0.0073331879 | AZ7: 0.0072018566 | BA7: 0.0072347426 | BB7: 0.0071923121 | BC7: 0.0071072373 | BD7: 0.0075968105 | BE7: 0.0076860827 | BF7: 0.0076302855 | BG7: -0.0011696573 | BH7: -0.0018117904 | BI7: -0.0012381344 | BJ7: -0.0016667121 | BK7: 0.0011854402 | BL7: -0.0026317847 | BM7: -0.0024695091 | BN7: -0.00023353244 | BO7: -0.00058625854 | BP7: -0.00029114341 | BQ7: -0.0012395748 | BR7: 0.00090124663 | BS7: 0.0022163231 | BT7: 0.0032838787 | BU7: 0.0027088049 | BV7: 0.0016313355 | BW7: 0.0018888554 | BX7: 0.0017888254 | BY7: 0.0016630493 | BZ7: 0.00064826212 | CA7: 0.0011734286 | CB7: 0.0018973786 | CC7: 0.00180233 | CD7: 0.0027409373 | CE7: -0.00045044868 | CF7: 0.0030292258 | CG7: 0.00088109861 | CH7: -0.0060081741
A8: Age71to72_Mixed | B8: 0.06841487 | C8: -0.0020541403 | D8: 4.1643355e-05 | E8: -0.0018034936 | F8: 0.00029294222 | G8: 0.031956518 | H8: 0.032901786 | I8: 0.055516418 | J8: 0.033001331 | K8: 0.033735727 | L8: 0.033476216 | M8: 0.033949084 | N8: 0.034302755 | O8: 0.034103938 | P8: 0.034399167 | Q8: -0.0041822747 | R8: -0.0037581961 | S8: -0.0030524323 | T8: -0.0060547365 | U8: 0.0010219917 | V8: 0.00075954112 | W8: -0.00075750881 | X8: -0.0029835848 | Y8: 6.4985318e-05 | Z8: 0.0013826696 | AA8: -0.00018146477 | AB8: -0.001325321 | AC8: 0.0036135778 | AD8: -0.00059681758 | AE8: -0.0001175259 | AF8: -0.0032375605 | AG8: -0.0031341658 | AH8: -0.0017805001 | AI8: -0.0042592463 | AJ8: -0.0052823001 | AK8: -0.0034398732 | AL8: -0.0014669631 | AM8: -0.0020328275 | AN8: -0.002183517 | AO8: -0.00033659814 | AP8: 0.0018576706 | AQ8: 0.0032917754 | AR8: -0.027084208 | AS8: -0.0011390439 | AT8: -0.001011093 | AU8: -0.00055674503 | AV8: 7.0069623e-05 | AW8: 0.0069485945 | AX8: 0.0070459597 | AY8: 0.01450969 | AZ8: 0.0072128885 | BA8: 0.0073004656 | BB8: 0.0070336454 | BC8: 0.0071546947 | BD8: 0.0075806041 | BE8: 0.0074116391 | BF8: 0.0073247657 | BG8: -0.0014805934 | BH8: -0.0015055445 | BI8: -0.0008867653 | BJ8: -0.0032213942 | BK8: 0.00057360357 | BL8: 0.00028719953 | BM8: -0.00019140723 | BN8: -0.00066588773 | BO8: 8.9321526e-05 | BP8: 0.00084218597 | BQ8: -0.00050050371 | BR8: 0.00015594468 | BS8: 0.0011604061 | BT8: 0.0006678694 | BU8: 0.00031946178 | BV8: -0.00019464653 | BW8: 0.00024744023 | BX8: 0.00020321957 | BY8: -0.00012927734 | BZ8: -0.0012371177 | CA8: -0.00038751575 | CB8: 0.00016438305 | CC8: 2.3997251e-06 | CD8: 0.00016591586 | CE8: 0.00034282047 | CF8: 0.0011959515 | CG8: 0.001194269 | CH8: -0.0061158276
